Workbook

Sheet Kangatang

Sheet PL03a
A2: BẢNG XÁC ĐỊNH GIÁ TRỊ KHỐI LƯỢNG CÔNG VIỆC HOÀN THÀNH THANH TOÁN LẦN THỨ: LẦN 01
A4: STT | B4: Tên công việc | C4: Đơn vị tính | D4: Quy cách kỹ thuật | E4: Thương hiệu | F4: Khối lượng | G4: Đơn giá
F5: Khối lượng theo hợp đồng
H6: Ghi chú
A7: 22 | B7: THIẾT BỊ ĐIỆN NHẸ
A8: 22.1 | B8: Hệ thống mạng - phần thiết bị
A9: 22.1.1 | B9: Core switch 24 SFP | C9: bộ | D9: ICX 7550 24 port | E9: Ruckus | F9: 1
A10: 22.1.2 | B10: Bộ máy tính server | C10: bộ | E10: Dell | F10: 1
A11: 22.1.3 | B11: Router Load balance | C11: bộ | D11: BLP-70 | E11: Ruckus | F11: 1
A12: 22.1.4 | B12: WIFI CONTROLLER | C12: bộ | D12: P01-S144-UK00 S02-S144-3000 377*L09-0001-SG00 377*S02-0001-3LSG | E12: Ruckus | F12: 1
A13: 22.2 | B13: Hệ thống mạng
A14: 22.2.1 | B14: Wifi gắn tường | C14: bộ | D14: RUIJIE REYEE RG-RAP2200€ | E14: Ruijie | F14: 274
A15: 22.2.2 | B15: Wifi âm trần | C15: bộ | D15: Bộ phát Wifi Ruijie Reyee RG-RAP6260(G) AX1800 Wi-Fi 6 Dual | E15: Ruijie | F15: 63
A16: 22.2.3 | B16: Switch poe 6p cổng RJ45 10/100/100 | C16: chiếc | D16: Switch POE 6 cổng 10/100/1000BASE-T Ruijie Reyee RG-ES206GC-P | E16: Ruijie | F16: 3
A17: 22.2.4 | B17: Switch poe 8p cổng RJ45 10/100/100 | C17: chiếc | D17: Switch 8 cổng 10/100/1000 BASE-T RUIJIE RG-NBS3100-8GT2SFP | E17: Ruijie | F17: 1
A18: 22.2.5 | B18: Switch poe 12p cổng RJ45 10/100/100 | C18: chiếc | D18: ICX7150-C12P-2X1G | E18: Ruckus | F18: 3
A19: 22.2.6 | B19: Switch poe 24p cổng RJ45 10/100/100 | C19: chiếc | D19: ICX8200-24P | E19: Ruckus | F19: 12
A20: 22.2.7 | B20: Switch 4p cổng RJ45 10/100/100 | C20: chiếc | D20: Switch POE 4 cổng RUIJIE REYEE RG-ES205GC-P | E20: Ruijie | F20: 1
A21: 22.2.8 | B21: Switch 6p cổng RJ45 10/100/100 | C21: chiếc | D21: Switch POE 6 cổng 10/100/1000BASE-T Ruijie Reyee RG-ES206GC-P | E21: Ruijie | F21: 2
A22: 22.2.9 | B22: Switch 8p cổng RJ45 10/100/100 | C22: chiếc | D22: Switch 8 cổng 10/100/1000 BASE-T RUIJIE RG-NBS3100-8GT2SFP | E22: Ruijie | F22: 1
A23: 22.2.10 | B23: Switch 12p cổng RJ45 10/100/100 | C23: chiếc | D23: ICX7150-C12P-2X1G | E23: Ruckus | F23: 2
A24: 22.2.11 | B24: Switch 24p cổng RJ45 10/100/100 | C24: chiếc | D24: ICX7150-24-4X1G | E24: Ruckus | F24: 13
A25: 22.2.12 | B25: Patch Panel 4p | C25: chiếc | E25: Legrand | F25: 1
A26: 22.2.13 | B26: Patch Panel 6p | C26: chiếc | E26: Legrand | F26: 5
A27: 22.2.14 | B27: Patch Panel 8p | C27: chiếc | E27: Legrand | F27: 2
A28: 22.2.15 | B28: Patch Panel 12p | C28: chiếc | E28: Legrand | F28: 4
A29: 22.2.16 | B29: Patch Panel 24p | C29: chiếc | E29: Legrand | F29: 25
A30: 22.3 | B30: HỆ THỐNG ĐIỆN THOẠI - PHẦN THIẾT BỊ
A31: 22.3.1 | B31: Tổng đài điện thoại IP 30 trung kế số, 128 máy tính | C31: bộ | D31: Tổng đài Yeastar MyPBX S300 | E31: Yeastar | F31: 3
A32: 22.3.2 | B32: Điện thoại IP Phone Sử dụng cho việc lập trình phím bấm, hiển thị cuộc gọi | C32: Chiếc | D32: Điện thoại IP Yealink SIP-T53W | E32: Yealink | F32: 1
A33: 22.3.3 | B33: Phần mềm tính cước (Thống kê cước nội bộ, thống kế theo số máy lẻ và nhóm người dùng; Lọc các cuộc gọi theo thời gian linh hoạt; Thực hiện hiệu chỉnh để phù hợp với giá cước của Bưu điện và Tổng đài; Phân quyền sử dụng và quản trị). | C33: License | D33: Yeastar S50 | E33: YEASTAR | F33: 1
A34: 22.3.4 | B34: Máy in cước laser đen trắng. Khổ giấy: A4/A5. In đảo mặt: Không. Cổng giao tiếp: USB/ LAN | C34: bộ | D34: HL-L2321D Máy in Laser | E34: Laser | F34: 1
A35: 22.4 | B35: HỆ THỐNG CAMERA GIÁM SÁT AN NINH - PHẦN THIẾT BỊ
A36: 22.4.1 | B36: Camera dome hồng ngoại 4Megapixe | C36: bộ | D36: Camera IP 4MP Dome DAHUA DH-IPC-HDW2441T-S | E36: Dahua | F36: 104
A37: 22.4.2 | B37: Camera thân hồng ngoại 4Megapixe | C37: bộ | D37: Camera IP thân trụ 4MP DAHUA DH-IPC-HFW2441TP-ZS | E37: Dahua | F37: 8
A38: 22.4.3 | B38: Camera Speeddome 2.0 Megapixel (OUR DOOR/ INDOOR) | C38: bộ | D38: Camera IP Speed Dome 2MP DAHUA DH-SD49225DB-HNY | F38: 12
A39: 22.4.4 | B39: Đầu ghi hình 32 kênh camera IP 1.5U 4HDD và phụ kiện | C39: bộ | D39: Đầu ghi hình IP 32 kênh DAHUA DHI-NVR5432-EI | F39: 6
A40: 22.4.5 | B40: Ổ cứng chuyên dụng 6TB 3.5", 64Mb Cache, SATA 3,hỗ trợ RAID, hoạt động 24/7 | C40: chiếc | D40: Ổ cứng gắn trong SEAGATE HDD SkyHawk 6TB, 5400 RPM, Cache 256MB (ST6000VX009) | F40: 6
A41: 22.4.6 | B41: Màn hình hiển thị camera Full HD 49" kèm giá treo tường | C41: chiếc | D41: Màn hình quảng cáo LG 50UL3J | F41: 6
A42: 22.4.7 | B42: Bộ máy chủ 21" | C42: bộ | E42: Dell | F42: 1
...

Sheet Sheet2
B3: HĐ | C3: tạm ứng lần 1 | D3: tạm ứng lần 2 | E3: Ttlần 1 | F3: tổng tiền đã nhận
A4: Tân Khánh hoà | B4: =PL03a!#REF! -> #REF! | C4: =H6-D4 -> #REF! | D4: 42388366000 | E4: =PL03a!#REF! -> #REF! | F4: =C4+D4+E4 -> #REF!
A5: Đường bộ | B5: 3469422000 | C5: =ROUND(B5*0.3,-3) -> 1040827000 | D5: =ROUND(B5*0.2,-3) -> 693884000 | E5: 1199602000 | F5: =C5+D5+E5 -> 2934313000
A6: Đường bộ - mua sắm | B6: 37512999000 | C6: 18756499000 | F6: =C6+D6+E6 -> 18756499000 | H6: =PL03a!#REF! -> #REF!
A7: tổng cộng | B7: =SUM(B4:B6) -> #REF! | C7: =SUM(C4:C6) -> #REF! | D7: =SUM(D4:D6) -> 43082250000 | E7: =SUM(E4:E6) -> #REF! | F7: =SUM(F4:F6) -> #REF!

Sheet Sheet1
K7: Khánh Hòa, ngày tháng năm 20
C9: ĐẠI DIỆN ĐƠN VỊ THI CÔNG | K9: ĐẠI DIỆN CHỦ ĐẦU TƯ
A11: Công ty TNHH Tân Khánh Hòa KH | F11: Công ty TNHH Cơ điện Khánh Hòa
A18: Công ty cổ phần Quản lý và Xây dựng đường bộ Khánh Hòa | F18: Công ty cổ phần Cơ điện lạnh Đông Sapa
K30: Khánh Hòa, ngày tháng năm 20
B32: ĐẠI DIỆN ĐƠN VỊ THI CÔNG | K32: ĐẠI DIỆN CHỦ ĐẦU TƯ

Sheet BBNTHT
A2: CỘNG HÒA XÃ HỘI CHỦ NGHĨA VIỆT NAM
A3: Độc lập - Tự do - Hạnh phúc
D4: Khánh Hòa, ngày …... tháng …..năm 2024.
A5: BIÊN BẢN NGHIỆM THU KHỐI LƯỢNG HOÀN THÀNH ĐỢT 1
A7: Gói thầu: Thi công xây dựng toàn bộ các hạng mục công trình và lắp đặt thiết bị trạm biến áp 1.600KVA, máy phát điện dự phòng 670KVA, hệ thống điện nhẹ, hệ thống điều hòa thông gió, hệ thống PCCC, máy bơm nước sinh hoạt, hệ thống nước nóng
A8: Dự án: Nhà khách Công an tỉnh Khánh Hòa
A9: Địa điểm: 78 Tuệ Tĩnh, phường Lộc Thọ, thành phố Nha Trang, Khánh Hòa
A11: I. THÀNH PHẦN THAM GIA NGHIỆM THU:
A12: 1. Đại diện Chủ đầu tư: Công an tỉnh Khánh Hòa
B13: - Ông: Nguyễn Văn Ngàn | C13: Chức vụ: Phó giám đốc
B14: - Ông: Đường Trung Thành | C14: Chức vụ: Trưởng phòng PH10
B15: - Ông: Lương Duy Quốc Tuấn | C15: Chức vụ: Đội trưởng đội XD-ĐT phòng PH10
A16: 2. Đại diện Tư vấn Quản lý dự án: Công ty Cổ phần Tư vấn Quản lý dự án Việt Nam
B17: - Ông: Nguyễn Cảnh Tiến | C17: Chức vụ: Giám đốc Công ty
B18: - Ông: Nguyễn Văn Nam | C18: Chức vụ: PGĐ QLDA
A19: 3. Đại diện đơn vị giám sát: Công ty Cổ phần Coninco – Thăng Long
B20: - Ông: Đặng Văn Bắc | C20: Chức vụ: Phó tổng giám đốc
B21: - Ông: Đặng Thái Sơn | C21: Chức vụ: Giám sát trưởng
B22: - Ông: Ngô Chí | C22: Chức vụ: CB Giám sát
B23: - Ông: | C23: Chức vụ: CB Giám sát
A24: 4. Đại diện đơn vị thi công: Liên danh thi công Nhà khách CA tỉnh Khánh Hòa
A25: 4.1 | B25: Thành viên Liên danh: Công ty TNHH Tân Khánh Hòa KH
B26: - Ông: Võ Đình Khang | C26: Chức vụ: Giám đốc
B27: - Ông: Huỳnh Tấn Khánh | C27: Chức vụ: Chỉ huy trưởng
A28: 4.2 | B28: Thành viên Liên danh: Công ty TNHH Cơ điện Khánh Hòa
B29: - Ông: Trương Sỹ Trường | C29: Chức vụ: Giám đốc
B30: - Ông: | C30: Chức vụ: Chỉ huy trưởng
A31: 4.3 | B31: Thành viên Liên danh: Công ty cổ phần Quản lý và Xây dựng đường bộ Khánh Hòa
B32: - Ông: Lê Thuận Đoàn | C32: Chức vụ: Giám đốc
B33: - Ông: | C33: Chức vụ: Chỉ huy trưởng
A34: 4.4 | B34: Thành viên Liên danh: Công ty cổ phần Cơ điện lạnh Đông Sapa
B35: - Ông: Nguyễn Phú Hữu | C35: Chức vụ: Giám đốc
B36: - Ông: | C36: Chức vụ: Chỉ huy trưởng
A37: II. THỜI GIAN NGHIỆM THU:
B38: - Bắt đầu : 08 giờ 00 phút, ngày….. tháng…...năm 2024.
B39: - Kết thúc: 10 giờ 30 phút, ngày….. tháng ….năm 2024.
B40: - Địa điểm: Tại công trình thi công.
A41: III. ĐÁNH GIÁ CÔNG VIỆC XÂY DỰNG ĐÃ THỰC HIỆN:
A42: 1. Về tài liệu làm căn cứ nghiệm thu:
A43: 1. Về tài liệu làm căn cứ nghiệm thu:
...

Sheet PL 03 liên danh
L1: Mẫu số 03a/TT
A2: BẢNG XÁC ĐỊNH GIÁ TRỊ KHỐI LƯỢNG CÔNG VIỆC HOÀN THÀNH THANH TOÁN LẦN THỨ: LẦN 01
A3: Tên dự án: Nhà khách Công an tỉnh Khánh Hòa; Mã dự án: 7004692
A4: Tên gói thầu XL01: Hợp đồng thi công xây dựng công trình
A5: Căn cứ hợp đồng số: 2706/2024/HĐXD ngày 27 tháng 6 năm 2024; Phụ lục Hợp đồng số 2706A/2024/HĐXD ngày 06/11/2024 ; Phụ lục Hợp đồng số 2706B/2024/HĐXD ngày….../12/2024 và Phụ lục Hợp đồng số 2706C/2024/HĐXD ngày ….../12/2024
A6: Căn cứ Quyết định phê duyệt dự toán số (trong trường hợp thực hiện không thông qua hợp đồng):…..ngày tháng năm 2024
A7: Chủ đầu tư: Công an tỉnh Khánh Hoà
A8: Nhà thầu: Liên danh thi công nhà khách Công an tỉnh Khánh Hoà
A9: Thanh toán lần thứ: 01 ( Phần khối lượng do liên danh thi công Nhà khách Công an tỉnh Khánh Hòa thực hiện)
A10: Căn cứ xác định:
A11: Biên bản nghiệm thu khối lượng hoàn thành đợt 01 ngày…… tháng …. .năm 2024.
L12: Đơn vị: Đồng
A13: STT | B13: Tên công việc | C13: Đơn vị tính | D13: Khối lượng | H13: Đơn giá thanh toán theo hợp đồng | I13: Thành tiền
D14: Khối lượng theo hợp đồng | E14: Thực hiện | I14: =D14 -> Khối lượng theo hợp đồng | J14: Thực hiện
E15: Lũy kế đến hết kỳ trước | F15: Thực hiện kỳ này | G15: Lũy kế đến hết kỳ này | J15: =E15 -> Lũy kế đến hết kỳ trước | K15: Thực hiện kỳ này | L15: =G15 -> Lũy kế đến hết kỳ này | M15: Ghi chú
A16: 1 | B16: PHẦN CỌC
A17: 1.1 | B17: Cọc PHC D600 Class A | C17: m | D17: 6556.9 | F17: =BBNTHT!J57 -> 5901.21 | G17: =F17+E17 -> 5901.21 | H17: 1092176 | I17: =ROUND(D17*H17,0) -> 7161288814 | K17: =ROUND(F17*H17,0) -> 6445159933 | L17: =J17+K17 -> 6445159933
A18: 1.2 | B18: Mũi cọc | C18: cái | D18: 203 | F18: =BBNTHT!J58 -> 203 | G18: =F18+E18 -> 203 | H18: 304794 | I18: =ROUND(D18*H18,0) -> 61873182 | K18: =ROUND(F18*H18,0) -> 61873182 | L18: =J18+K18 -> 61873182
A19: 1.3 | B19: Khoan dẫn phục vụ đóng, ép cọc bằng máy khoan xoay, đường kính 400mm | C19: m | D19: 2892.75 | F19: =BBNTHT!J59 -> 2169.5625 | G19: =F19+E19 -> 2169.5625 | H19: 1009270 | I19: =ROUND(D19*H19,0) -> 2919565793 | K19: =ROUND(F19*H19,0) -> 2189674344 | L19: =J19+K19 -> 2189674344
A20: 1.4 | B20: Ép cọc ống bê tông cốt thép dự ứng lực bằng máy ép Robot thủy lực tự hành, đất cấp I, đường kính cọc 600mm | C20: 100m | D20: 57.631 | F20: =BBNTHT!J60 -> 43.22325 | G20: =F20+E20 -> 43.22325 | H20: 23523671 | I20: =ROUND(D20*H20,0) -> 1355692683 | K20: =ROUND(F20*H20,0) -> 1016769513 | L20: =J20+K20 -> 1016769513
A21: 1.5 | B21: Ép cọc ống bê tông cốt thép dự ứng lực bằng máy ép Robot thủy lực tự hành, đất cấp I, đường kính cọc 600mm, đoạn cọc không ngập đất | C21: 100m | D21: 0.006 | F21: =BBNTHT!J61 -> 0 | G21: =F21+E21 -> 0 | H21: 17642753 | I21: =ROUND(D21*H21,0) -> 105857 | K21: =ROUND(F21*H21,0) -> 0 | L21: =J21+K21 -> 0
A22: 1.6 | B22: Ép cọc ống bê tông cốt thép dự ứng lực bằng máy ép Robot thủy lực tự hành , đất cấp I, đường kính cọc 600mm, ép âm sử dụng cọc dẫn | C22: 100m | D22: 6.729 | F22: =BBNTHT!J62 -> 0 | G22: =F22+E22 -> 0 | H22: 24699855 | I22: =ROUND(D22*H22,0) -> 166205324 | K22: =ROUND(F22*H22,0) -> 0 | L22: =J22+K22 -> 0
A23: 1.7 | B23: Nối cọc ống bê tông cốt thép, đường kính cọc <= 600mm | C23: mối nối | D23: 203 | F23: =BBNTHT!J63 -> 0 | G23: =F23+E23 -> 0 | H23: 622096 | I23: =ROUND(D23*H23,0) -> 126285488 | K23: =ROUND(F23*H23,0) -> 0 | L23: =J23+K23 -> 0
A24: 1.8 | B24: Cắt đầu cọc | C24: mối | D24: 203 | F24: =BBNTHT!J64 -> 0 | G24: =F24+E24 -> 0 | H24: 281360 | I24: =ROUND(D24*H24,0) -> 57116080 | K24: =ROUND(F24*H24,0) -> 0 | L24: =J24+K24 -> 0
A25: 1.9 | B25: Vận chuyển đất bằng ôtô tự đổ trong phạm vi <= 1000m, đất cấp III | C25: 100m3 | D25: 0.344 | F25: =BBNTHT!J65 -> 0 | G25: =F25+E25 -> 0 | H25: 3030140 | I25: =ROUND(D25*H25,0) -> 1042368 | K25: =ROUND(F25*H25,0) -> 0 | L25: =J25+K25 -> 0
A26: 1.10 | B26: Vận chuyển đất bằng ô tô tự đổ 1km tiếp theo ngoài phạm vi 5km, đất cấp III | C26: 100m3 | D26: 0.344 | F26: =BBNTHT!J66 -> 0 | G26: =F26+E26 -> 0 | H26: 3561537 | I26: =ROUND(D26*H26,0) -> 1225169 | K26: =ROUND(F26*H26,0) -> 0 | L26: =J26+K26 -> 0
A27: 1.11 | B27: Gia công cấu kiện thép đặt sẵn trong bê tông, khối lượng một cấu kiện <= 50 kg | C27: tấn | D27: 9.354 | F27: =BBNTHT!J67 -> 0 | G27: =F27+E27 -> 0 | H27: 38704566 | I27: =ROUND(D27*H27,0) -> 362042510 | K27: =ROUND(F27*H27,0) -> 0 | L27: =J27+K27 -> 0
A28: 1.12 | B28: Lắp đặt cấu kiện thép đặt sẵn trong bê tông, khối lượng một cấu kiện <= 50 kg | C28: tấn | D28: 9.354 | F28: =BBNTHT!J68 -> 0 | G28: =F28+E28 -> 0 | H28: 5407084 | I28: =ROUND(D28*H28,0) -> 50577864 | K28: =ROUND(F28*H28,0) -> 0 | L28: =J28+K28 -> 0
A29: 1.13 | B29: Đổ bê tông thủ công bằng máy trộn, bê tông móng, chiều rộng <= 250 cm, đá 1x2, mác 300 | C29: m3 | D29: 53.409 | F29: =BBNTHT!J69 -> 0 | G29: =F29+E29 -> 0 | H29: 1703602 | I29: =ROUND(D29*H29,0) -> 90987679 | K29: =ROUND(F29*H29,0) -> 0 | L29: =J29+K29 -> 0
A30: 2 | B30: PHẦN DƯỚI CỐT 0.0M | F30: =BBNTHT!J70 -> 0 | G30: =F30+E30 -> 0 | K30: =ROUND(F30*H30,0) -> 0 | L30: =J30+K30 -> 0
A31: 2.1 | B31: Đào móng công trình, chiều rộng móng ≤6m, bằng máy đào, đất cấp II | C31: 100m3 | D31: 48.676 | F31: =BBNTHT!J71 -> 0 | G31: =F31+E31 -> 0 | H31: 2235933 | I31: =ROUND(D31*H31,0) -> 108836275 | K31: =ROUND(F31*H31,0) -> 0 | L31: =J31+K31 -> 0
A32: 2.2 | B32: Đắp đất công trình bằng đầm đất cầm tay, độ chặt yêu cầu K=0,85 | C32: 100m3 | D32: 1.31 | F32: =BBNTHT!J72 -> 0 | G32: =F32+E32 -> 0 | H32: 3013626 | I32: =ROUND(D32*H32,0) -> 3947850 | K32: =ROUND(F32*H32,0) -> 0 | L32: =J32+K32 -> 0
A33: 2.3 | B33: Vận chuyển đất bằng ôtô tự đổ trong phạm vi ≤1000m, đất cấp II | C33: 100m3 | D33: 47.235 | F33: =BBNTHT!J73 -> 0 | G33: =F33+E33 -> 0 | H33: 2359400 | I33: =ROUND(D33*H33,0) -> 111446259 | K33: =ROUND(F33*H33,0) -> 0 | L33: =J33+K33 -> 0
A34: 2.4 | B34: Vận chuyển đất bằng ô tô tự đổ 1km tiếp theo trong phạm vi ≤5km, đất cấp II | C34: 100m3 | D34: 47.235 | F34: =BBNTHT!J74 -> 0 | G34: =F34+E34 -> 0 | H34: 4024442 | I34: =ROUND(D34*H34,0) -> 190094518 | K34: =ROUND(F34*H34,0) -> 0 | L34: =J34+K34 -> 0
A35: 2.5 | B35: Bê tông lót móng, chiều rộng ≤250cm, đá 4x6, mác 100 | C35: m3 | D35: 157.661 | F35: =BBNTHT!J75 -> 0 | G35: =F35+E35 -> 0 | H35: 1223510 | I35: =ROUND(D35*H35,0) -> 192899810 | K35: =ROUND(F35*H35,0) -> 0 | L35: =J35+K35 -> 0
A36: 2.6 | B36: Lớp màng chống thấm tự dính dày 2mm | C36: m2 | D36: 875.73 | F36: =BBNTHT!J76 -> 0 | G36: =F36+E36 -> 0 | H36: 190495 | I36: =ROUND(D36*H36,0) -> 166822186 | K36: =ROUND(F36*H36,0) -> 0 | L36: =J36+K36 -> 0
A37: 2.7 | B37: Láng nền sàn không đánh mầu,vữa XM mác 50 | C37: m2 | D37: 875.73 | F37: =BBNTHT!J77 -> 0 | G37: =F37+E37 -> 0 | H37: 45008 | I37: =ROUND(D37*H37,0) -> 39414856 | K37: =ROUND(F37*H37,0) -> 0 | L37: =J37+K37 -> 0
A38: 2.8 | B38: Đổ bê tông bằng máy, đổ bằng máy bơm bê tông, bê tông móng, chiều rộng móng ≤250cm, đá 1x2, mác 400 | C38: m3 | D38: 9.075 | F38: =BBNTHT!J78 -> 0 | G38: =F38+E38 -> 0 | H38: 2243046 | I38: =ROUND(D38*H38,0) -> 20355642 | K38: =ROUND(F38*H38,0) -> 0 | L38: =J38+K38 -> 0
A39: 2.9 | B39: Đổ bê tông bằng máy, đổ bằng máy bơm bê tông, bê tông móng, chiều rộng móng >250cm, đá 1x2, mác 400 | C39: m3 | D39: 1025.075 | F39: =BBNTHT!J79 -> 0 | G39: =F39+E39 -> 0 | H39: 2343243 | I39: =ROUND(D39*H39,0) -> 2401999818 | K39: =ROUND(F39*H39,0) -> 0 | L39: =J39+K39 -> 0
A40: 2.10 | B40: Ván khuôn móng cột | C40: 100m2 | D40: 8.564 | F40: =BBNTHT!J80 -> 0 | G40: =F40+E40 -> 0 | H40: 12390253 | I40: =ROUND(D40*H40,0) -> 106110127 | K40: =ROUND(F40*H40,0) -> 0 | L40: =J40+K40 -> 0
...

Sheet bảng diễn giải
A5: STT | B5: Diễn giải khối lượng | C5: Đơn vị | D5: Số lượng | E5: Kích thước | H5: Hệ số | I5: Khối lượng
E6: Dài | F6: Rộng | G6: Cao | I6: Chi tiết | J6: Theo HĐ | K6: Thực hiện kỳ này | L6: Lũy kế đến hết kỳ trước | M6: Thanh toán kỳ này | N6: Lũy kế đến hết kỳ này
A7: 1 | B7: 2 | C7: 3 | D7: 4 | E7: 5 | F7: 6 | G7: 7 | H7: 8 | I7: 9 | J7: 10 | K7: 11 | L7: 12 | M7: 13 | N7: 14
B8: HẠNG MỤC: PHẦN CỌC
A9: 1 | B9: Cọc PHC D600 Class A | C9: m | I9: =ROUND(SUM(I10:I11),3) -> 6556.9 | J9: =PL03a!#REF! -> #REF! | K9: =I9 -> 6556.9 | M9: =K9 -> 6556.9 | N9: =L9+M9 -> 6556.9
B10: Cọc thí nghiệm | D10: 2 | E10: 32.3 | I10: =ROUND(PRODUCT(D10:E10),3) -> 64.6
B11: Cọc đại trà loại 1 | D11: 201 | E11: =32+0.3 -> 32.3 | I11: =ROUND(PRODUCT(D11:E11),3) -> 6492.3
A12: 2 | B12: Mũi cọc | C12: cái | I12: =ROUND(SUM(I13:I14),3) -> 203 | J12: =PL03a!#REF! -> #REF! | K12: =I12 -> 203 | M12: =K12 -> 203 | N12: =L12+M12 -> 203
B13: Cọc thí nghiệm | D13: 2 | I13: =ROUND(PRODUCT(D13:E13),3) -> 2
B14: Cọc đại trà loại 1 | D14: 201 | I14: =ROUND(PRODUCT(D14:E14),3) -> 201
A15: 3 | B15: Khoan dẫn phục vụ đóng, ép cọc bằng máy khoan xoay, đường kính 400mm | C15: m | I15: =ROUND(SUM(I16:I18),3) -> 4466 | J15: =PL03a!#REF! -> #REF! | K15: =I15 -> 4466 | M15: =J15 -> #REF! | N15: =L15+M15 -> #REF!
B16: Phần đất cát:
B17: Cọc thí nghiệm | D17: 2 | E17: 22 | I17: =ROUND(PRODUCT(D17:E17),3) -> 44
B18: Cọc đại trà loại 1 | D18: 201 | E18: 22 | I18: =ROUND(PRODUCT(D18:E18),3) -> 4422
A19: 4 | B19: Ép cọc ống bê tông cốt thép dự ứng lực bằng máy ép Robot thủy lực tự hành 860T, đất cấp I, đường kính cọc 600mm | C19: 100m | I19: =ROUND(SUM(I20:I23),3) -> 57.631 | J19: =PL03a!#REF! -> #REF! | K19: =I19 -> 57.631 | M19: =K19 -> 57.631 | N19: =L19+M19 -> 57.631
B20: Cọc thí nghiệm | D20: 2 | E20: 32 | H20: 0.01 | I20: =ROUND(PRODUCT(D20:H20),3) -> 0.64
B21: Cọc đại trà loại 1, dưới đài cọc cao 1.5m | D21: 11 | E21: 28.95 | H21: 0.01 | I21: =ROUND(PRODUCT(D21:H21),3) -> 3.185
B22: Cọc đại trà loại 1, dưới đài cọc cao 2.0m | D22: 165 | E22: 28.45 | H22: 0.01 | I22: =ROUND(PRODUCT(D22:H22),3) -> 46.943
B23: Cọc đại trà loại 1, dưới đài cọc cao 3.0m | D23: 25 | E23: 27.45 | H23: 0.01 | I23: =ROUND(PRODUCT(D23:H23),3) -> 6.863
A24: 5 | B24: Ép cọc ống bê tông cốt thép dự ứng lực bằng máy ép Robot thủy lực tự hành 860T, đất cấp I, đường kính cọc 600mm, đoạn cọc không ngập đất (NC, MTC x 0.75) | C24: 100m | I24: =ROUND(SUM(I25:I25),3) -> 0.006 | J24: =PL03a!#REF! -> #REF! | K24: =I24 -> 0.006 | M24: =K24 -> 0.006 | N24: =L24+M24 -> 0.006
B25: Cọc thí nghiệm | D25: 2 | E25: 0.3 | H25: 0.01 | I25: =ROUND(PRODUCT(D25:H25),3) -> 0.006 | K25: =I25 -> 0.006 | M25: =K25 -> 0.006 | N25: =L25+M25 -> 0.006
A26: 6 | B26: Ép cọc ống bê tông cốt thép dự ứng lực bằng máy ép Robot thủy lực tự hành 860T, đất cấp I, đường kính cọc 600mm, ép âm sử dụng cọc dẫn (NC, MTC x 1.05) | C26: 100m | I26: =ROUND(SUM(I27:I29),3) -> 6.729 | J26: =PL03a!#REF! -> #REF! | K26: =I26 -> 6.729 | M26: =K26 -> 6.729 | N26: =L26+M26 -> 6.729
B27: Cọc đại trà loại 1, dưới đài cọc cao 1.5m | D27: 11 | E27: 2.75 | H27: 0.01 | I27: =ROUND(PRODUCT(D27:H27),3) -> 0.303
B28: Cọc đại trà loại 1, dưới đài cọc cao 2.0m | D28: 165 | E28: 3.25 | H28: 0.01 | I28: =ROUND(PRODUCT(D28:H28),3) -> 5.363
B29: Cọc đại trà loại 1, dưới đài cọc cao 3.0m | D29: 25 | E29: 4.25 | H29: 0.01 | I29: =ROUND(PRODUCT(D29:H29),3) -> 1.063
A30: 7 | B30: Nối cọc ống bê tông cốt thép, đường kính cọc <= 600mm | C30: mối nối | E30: 203 | I30: =ROUND(PRODUCT(D30:E30),3) -> 203 | J30: =PL03a!#REF! -> #REF! | K30: =I30 -> 203 | M30: =K30 -> 203 | N30: =L30+M30 -> 203
A31: 8 | B31: Cắt đầu cọc (VD mã hiệu) | C31: mối | I31: =ROUND(SUM(I32:I33),3) -> 205 | J31: 203 | K31: =I31 -> 205 | M31: =J31 -> 203 | N31: =L31+M31 -> 203
B32: Cọc thí nghiệm | D32: 4 | I32: =ROUND(PRODUCT(D32:E32),3) -> 4
B33: Cọc đại trà loại 1 | D33: 201 | I33: =ROUND(PRODUCT(D33:E33),3) -> 201
A34: 9 | B34: Vận chuyển đất bằng ôtô tự đổ 7 tấn trong phạm vi <= 1000m, đất cấp III | C34: 100m3 | I34: =I35 -> 0.3442068 | J34: =PL03a!#REF! -> #REF! | K34: =I34 -> 0.3442068 | M34: =K34 -> 0.3442068 | N34: =L34+M34 -> 0.3442068
B35: BT đầu cọc: 203*3,14*0,3*0,3*0,6*0,01 = 0,344 | I35: =203*3.14*0.3*0.3*0.6*0.01 -> 0.3442068
A36: 10 | B36: Vận chuyển đất bằng ô tô tự đổ 7T 1km tiếp theo ngoài phạm vi 5km, đất cấp III | C36: 100m3 | I36: =ROUND(SUM(I37:I37),3) -> 0.344 | J36: 3.44 | K36: =I36 -> 0.344 | M36: =K36 -> 0.344 | N36: =L36+M36 -> 0.344
B37: VC xa 5km, MTC x 4 | E37: =L34 -> 0 | I37: =I35 -> 0.3442068
A38: 11 | B38: Gia công cấu kiện thép đặt sẵn trong bê tông, khối lượng một cấu kiện <= 50 kg | C38: tấn | I38: =ROUND(SUM(I39:I39),3) -> 9.354 | J38: =PL03a!#REF! -> #REF! | K38: =I38 -> 9.354 | M38: =K38 -> 9.354 | N38: =L38+M38 -> 9.354
B39: Thép liên kết cọc với đài | D39: 203 | E39: =34.3+3.39+7.13+1.26 -> 46.08 | H39: 0.001 | I39: =ROUND(PRODUCT(D39:H39),3) -> 9.354
A40: 12 | B40: Lắp đặt cấu kiện thép đặt sẵn trong bê tông, khối lượng một cấu kiện <= 50 kg | C40: tấn | E40: =J38 -> #REF! | I40: =ROUND(PRODUCT(D40:E40),3) -> #REF! | J40: =PL03a!#REF! -> #REF! | K40: =I40 -> #REF! | M40: =K40 -> #REF! | N40: =L40+M40 -> #REF!
A41: 13 | B41: Đổ bê tông thủ công bằng máy trộn, bê tông móng, chiều rộng <= 250 cm, đá 1x2, mác 300 | C41: m3 | I41: =ROUND(SUM(I42:I42),3) -> 53.409 | J41: =PL03a!#REF! -> #REF! | K41: =I41 -> 53.409 | M41: =K41 -> 53.409 | N41: =L41+M41 -> 53.409
B42: BT chèn cọc ( tính theo đk trong của cọc) | D42: 203 | E42: 3.14 | F42: =0.21*0.21 -> 0.0441 | G42: 1.9 | I42: =ROUND(PRODUCT(D42:H42),3) -> 53.409
B43: HẠNG MỤC: PHẦN DƯỚI CỐT 0.0M
A44: 1 | B44: Đào móng công trình, chiều rộng móng ≤6m, bằng máy đào 1,25m3, đất cấp II | C44: 100m3 | I44: =SUM(I45:I141) -> 48.676 | J44: =PL03a!#REF! -> #REF! | K44: =I44 -> 48.676 | M44: =K44 -> 48.676 | N44: =L44+M44 -> 48.676
...

Sheet đọc số
D2: Số cần đọc: | G2: =PL03a!#REF! -> #REF!
B4: Số đọc | C4: Đọc chữ
A5: Hàng đơn vị | B5: =G5-10*G6 -> #REF! | C5: =IF(G5=0,"",IF(B5=0,"",IF(AND(B5=1,B6=1)," một",IF(AND(B5=1,B6>1)," mốt",IF(AND(B5=5,B6>0)," lăm",IF(G6=0,LOOKUP(B5,D5:D14,E5:E14),LOOKUP(B5,D5:D14,F5:F14))))))) -> #REF! | D5: 0 | E5: =IF(B5=0,""," Không") -> #REF! | F5: không | G5: =ROUND(G2,0) -> #REF!
A6: Hàng chục | B6: =G6-10*G7 -> #REF! | C6: =IF(G6=0,"",IF(AND(B6=0,B5=0),"",IF(AND(B6=0,B5>0)," lẻ",IF(AND(B6=1,G7<>0)," mười",IF(AND(B6=1,G7=0)," Mười",IF(B6>1,IF(G7=0,LOOKUP(B6,D5:D14,E5:E14),LOOKUP(B6,D5:D14,F5:F14)))))))&IF(B6>1," mươi","")) -> #REF! | D6: 1 | E6: Một | F6: một | G6: =ROUNDDOWN(G5/10,0) -> #REF!
A7: Hàng trăm | B7: =G7-10*G8 -> #REF! | C7: =IF(G7=0,"",IF(AND(B5=0,B6=0,B7=0),"",IF(AND(B7=0,B6>0)," không",IF(AND(B7=0,B5>0)," không",IF(G8=0,LOOKUP(B7,D5:D14,E5:E14),LOOKUP(B7,D5:D14,F5:F14)))))&IF(SUM(B5:B7)>0," trăm","")) -> #REF! | D7: 2 | E7: Hai | F7: hai | G7: =ROUNDDOWN(G6/10,0) -> #REF!
A8: Hàng nghìn | B8: =G8-10*G9 -> #REF! | C8: =IF(G8=0,"",IF(B8=0,"",IF(AND(B8=1,B9=1)," một",IF(AND(B8=1,B9>1)," mốt",IF(AND(B8=5,B9>0)," lăm",IF(G9=0,LOOKUP(B8,D5:D14,E5:E14),LOOKUP(B8,D5:D14,F5:F14))))))&IF(SUM(B8:B10)>0," nghìn","")) -> #REF! | D8: 3 | E8: Ba | F8: ba | G8: =ROUNDDOWN(G7/10,0) -> #REF!
A9: Hàng chục nghìn | B9: =G9-10*G10 -> #REF! | C9: =IF(G9=0,"",IF(AND(B9=0,B8=0),"",IF(AND(B9=0,B8>0)," lẻ",IF(AND(B9=1,G10<>0)," mười",IF(AND(B9=1,G10=0)," Mười",IF(B9>1,IF(G10=0,LOOKUP(B9,D5:D14,E5:E14),LOOKUP(B9,D5:D14,F5:F14)))))))&IF(B9>1," mươi","")) -> #REF! | D9: 4 | E9: Bốn | F9: bốn | G9: =ROUNDDOWN(G8/10,0) -> #REF!
A10: Hàng trăm nghìn | B10: =G10-10*G11 -> #REF! | C10: =IF(G10=0,"",IF(AND(B8=0,B9=0,B10=0),"",IF(AND(B10=0,B9>0)," không",IF(AND(B10=0,B8>0)," không",IF(G11=0,LOOKUP(B10,D5:D14,E5:E14),LOOKUP(B10,D5:D14,F5:F14)))))&IF(SUM(B8:B10)>0," trăm","")) -> #REF! | D10: 5 | E10: Năm | F10: năm | G10: =ROUNDDOWN(G9/10,0) -> #REF!
A11: Hàng triệu | B11: =G11-10*G12 -> #REF! | C11: =IF(G11=0,"",IF(B11=0,"",IF(AND(B11=1,B12=1)," một",IF(AND(B11=1,B12>1)," mốt",IF(AND(B11=5,B12>0)," lăm",IF(G12=0,LOOKUP(B11,D5:D14,E5:E14),LOOKUP(B11,D5:D14,F5:F14))))))&IF(SUM(B11:B13)>0," triệu,","")) -> #REF! | D11: 6 | E11: Sáu | F11: sáu | G11: =ROUNDDOWN(G10/10,0) -> #REF!
A12: Hàng chục triệu | B12: =G12-10*G13 -> #REF! | C12: =IF(G12=0,"",IF(AND(B12=0,B11=0),"",IF(AND(B12=0,B11>0)," lẻ",IF(AND(B12=1,G13<>0)," mười",IF(AND(B12=1,G13=0)," Mười",IF(B12>1,IF(G13=0,LOOKUP(B12,D5:D14,E5:E14),LOOKUP(B12,D5:D14,F5:F14)))))))&IF(B12>1," mươi","")) -> #REF! | D12: 7 | E12: Bảy | F12: bảy | G12: =ROUNDDOWN(G11/10,0) -> #REF!
A13: Hàng trăm triệu | B13: =G13-10*G14 -> #REF! | C13: =IF(G13=0,"",IF(AND(B11=0,B12=0,B13=0),"",IF(AND(B13=0,B12>0)," không",IF(AND(B13=0,B11>0)," không",IF(G14=0,LOOKUP(B13,D5:D14,E5:E14),LOOKUP(B13,D5:D14,F5:F14)))))&IF(SUM(B11:B13)>0," trăm","")) -> #REF! | D13: 8 | E13: Tám | F13: tám | G13: =ROUNDDOWN(G12/10,0) -> #REF!
A14: Hàng tỷ | B14: =G14-10*G15 -> #REF! | C14: =IF(G14=0,"",IF(B14=0,"",IF(AND(B14=1,B15=1)," một",IF(AND(B14=1,B15>1)," mốt",IF(AND(B14=5,B15>0)," lăm",IF(G15=0,LOOKUP(B14,D5:D14,E5:E14),LOOKUP(B14,D5:D14,F5:F14))))))&IF(SUM(B14:B20)>0," tỷ,","")) -> #REF! | D14: 9 | E14: Chín | F14: chín | G14: =ROUNDDOWN(G13/10,0) -> #REF!
A15: Hàng chục tỷ | B15: =G15-10*G16 -> #REF! | C15: =IF(G15=0,"",IF(AND(B15=0,B14=0),"",IF(AND(B15=0,B14>0)," lẻ",IF(AND(B15=1,G16<>0)," mười",IF(AND(B15=1,G16=0)," Mười",IF(B15>1,IF(G16=0,LOOKUP(B15,D5:D14,E5:E14),LOOKUP(B15,D5:D14,F5:F14)))))))&IF(B15>1," mươi","")) -> #REF! | G15: =ROUNDDOWN(G14/10,0) -> #REF!
A16: Hàng trăm tỷ | B16: =G16-10*G17 -> #REF! | C16: =IF(G16=0,"",IF(AND(B14=0,B15=0,B16=0),"",IF(AND(B16=0,B15>0)," không",IF(AND(B16=0,B14>0)," không",IF(G17=0,LOOKUP(B16,D5:D14,E5:E14),LOOKUP(B16,D5:D14,F5:F14)))))&IF(SUM(B14:B16)>0," trăm","")) -> #REF! | G16: =ROUNDDOWN(G15/10,0) -> #REF!
A17: Hàng nghìn tỷ | B17: =G17-10*G18 -> #REF! | C17: =IF(G17=0,"",IF(B17=0,"",IF(AND(B17=1,B18=1)," một",IF(AND(B17=1,B18>1)," mốt",IF(AND(B17=5,B18>0)," lăm",IF(G18=0,LOOKUP(B17,D5:D14,E5:E14),LOOKUP(B17,D5:D14,F5:F14))))))&IF(SUM(B17:B19)>0," nghìn","")) -> #REF! | G17: =ROUNDDOWN(G16/10,0) -> #REF!
A18: Hàng chục nghìn tỷ | B18: =G18-10*G19 -> #REF! | C18: =IF(G18=0,"",IF(AND(B18=0,B17=0),"",IF(AND(B18=0,B17>0)," lẻ",IF(AND(B18=1,G19<>0)," mười",IF(AND(B18=1,G19=0)," Mười",IF(B18>1,IF(G19=0,LOOKUP(B18,D5:D14,E5:E14),LOOKUP(B18,D5:D14,F5:F14)))))))&IF(B18>1," mươi","")) -> #REF! | G18: =ROUNDDOWN(G17/10,0) -> #REF!
A19: Hàng trăm nghìn tỷ | B19: =G19-10*B20 -> #REF! | C19: =IF(G19=0,"",IF(AND(B17=0,B18=0,B19=0),"",IF(AND(B19=0,B18>0)," không",IF(AND(B19=0,B17>0)," không",IF(G20=0,LOOKUP(B19,D5:D14,E5:E14),LOOKUP(B19,D5:D14,F5:F14)))))&IF(SUM(B17:B19)>0," trăm","")) -> #REF! | G19: =ROUNDDOWN(G18/10,0) -> #REF!
C20: =IF(G20=0,"",IF(B20=0,"",IF(AND(B20=1,#REF!=1)," một",IF(AND(B20=1,#REF!>1)," mốt",IF(AND(B20=5,#REF!>0)," lăm",IF(#REF!=0,LOOKUP(B20,D5:D14,E5:E14),LOOKUP(B20,D5:D14,F5:F14))))))&IF(SUM(B20:B20)>0," triệu",""))
A21: Với Font Unicode: Đọc số là:
G22: =""& IF(G5=0,"Không ",CONCATENATE(C19,C18,C17,C16,C15,C14,C13,C12,C11,C10,C9,C8,C7,C6,C5)) & " đồng" -> #REF!
A24: Với Font TCVN, VNI
B25: - Copy Vùng dữ liệu ở trên đến vị trí khác.
B26: - Thay đổi các chữ trong công thức ở vùng "C6:F20" bằng bảng mã TCVN
B27: hoặc VNI sẽ có được cách đọc tương ứng
D34: Số cần đọc: | G34: =PL03a!#REF! -> #REF!
B36: Số đọc | C36: Đọc chữ
A37: Hàng đơn vị | B37: =G37-10*G38 -> #REF! | C37: =IF(G37=0,"",IF(B37=0,"",IF(AND(B37=1,B38=1)," một",IF(AND(B37=1,B38>1)," mốt",IF(AND(B37=5,B38>0)," lăm",IF(G38=0,LOOKUP(B37,D37:D46,E37:E46),LOOKUP(B37,D37:D46,F37:F46))))))) -> #REF! | D37: 0 | E37: =IF(B37=0,""," Không") -> #REF! | F37: không | G37: =ROUND(G34,0) -> #REF!
A38: Hàng chục | B38: =G38-10*G39 -> #REF! | C38: =IF(G38=0,"",IF(AND(B38=0,B37=0),"",IF(AND(B38=0,B37>0)," lẻ",IF(AND(B38=1,G39<>0)," mười",IF(AND(B38=1,G39=0)," Mười",IF(B38>1,IF(G39=0,LOOKUP(B38,D37:D46,E37:E46),LOOKUP(B38,D37:D46,F37:F46)))))))&IF(B38>1," mươi","")) -> #REF! | D38: 1 | E38: Một | F38: một | G38: =ROUNDDOWN(G37/10,0) -> #REF!
A39: Hàng trăm | B39: =G39-10*G40 -> #REF! | C39: =IF(G39=0,"",IF(AND(B37=0,B38=0,B39=0),"",IF(AND(B39=0,B38>0)," không",IF(AND(B39=0,B37>0)," không",IF(G40=0,LOOKUP(B39,D37:D46,E37:E46),LOOKUP(B39,D37:D46,F37:F46)))))&IF(SUM(B37:B39)>0," trăm","")) -> #REF! | D39: 2 | E39: Hai | F39: hai | G39: =ROUNDDOWN(G38/10,0) -> #REF!
A40: Hàng nghìn | B40: =G40-10*G41 -> #REF! | C40: =IF(G40=0,"",IF(B40=0,"",IF(AND(B40=1,B41=1)," một",IF(AND(B40=1,B41>1)," mốt",IF(AND(B40=5,B41>0)," lăm",IF(G41=0,LOOKUP(B40,D37:D46,E37:E46),LOOKUP(B40,D37:D46,F37:F46))))))&IF(SUM(B40:B42)>0," nghìn","")) -> #REF! | D40: 3 | E40: Ba | F40: ba | G40: =ROUNDDOWN(G39/10,0) -> #REF!
A41: Hàng chục nghìn | B41: =G41-10*G42 -> #REF! | C41: =IF(G41=0,"",IF(AND(B41=0,B40=0),"",IF(AND(B41=0,B40>0)," lẻ",IF(AND(B41=1,G42<>0)," mười",IF(AND(B41=1,G42=0)," Mười",IF(B41>1,IF(G42=0,LOOKUP(B41,D37:D46,E37:E46),LOOKUP(B41,D37:D46,F37:F46)))))))&IF(B41>1," mươi","")) -> #REF! | D41: 4 | E41: Bốn | F41: bốn | G41: =ROUNDDOWN(G40/10,0) -> #REF!
A42: Hàng trăm nghìn | B42: =G42-10*G43 -> #REF! | C42: =IF(G42=0,"",IF(AND(B40=0,B41=0,B42=0),"",IF(AND(B42=0,B41>0)," không",IF(AND(B42=0,B40>0)," không",IF(G43=0,LOOKUP(B42,D37:D46,E37:E46),LOOKUP(B42,D37:D46,F37:F46)))))&IF(SUM(B40:B42)>0," trăm","")) -> #REF! | D42: 5 | E42: Năm | F42: năm | G42: =ROUNDDOWN(G41/10,0) -> #REF!
A43: Hàng triệu | B43: =G43-10*G44 -> #REF! | C43: =IF(G43=0,"",IF(B43=0,"",IF(AND(B43=1,B44=1)," một",IF(AND(B43=1,B44>1)," mốt",IF(AND(B43=5,B44>0)," lăm",IF(G44=0,LOOKUP(B43,D37:D46,E37:E46),LOOKUP(B43,D37:D46,F37:F46))))))&IF(SUM(B43:B45)>0," triệu,","")) -> #REF! | D43: 6 | E43: Sáu | F43: sáu | G43: =ROUNDDOWN(G42/10,0) -> #REF!
A44: Hàng chục triệu | B44: =G44-10*G45 -> #REF! | C44: =IF(G44=0,"",IF(AND(B44=0,B43=0),"",IF(AND(B44=0,B43>0)," lẻ",IF(AND(B44=1,G45<>0)," mười",IF(AND(B44=1,G45=0)," Mười",IF(B44>1,IF(G45=0,LOOKUP(B44,D37:D46,E37:E46),LOOKUP(B44,D37:D46,F37:F46)))))))&IF(B44>1," mươi","")) -> #REF! | D44: 7 | E44: Bảy | F44: bảy | G44: =ROUNDDOWN(G43/10,0) -> #REF!
A45: Hàng trăm triệu | B45: =G45-10*G46 -> #REF! | C45: =IF(G45=0,"",IF(AND(B43=0,B44=0,B45=0),"",IF(AND(B45=0,B44>0)," không",IF(AND(B45=0,B43>0)," không",IF(G46=0,LOOKUP(B45,D37:D46,E37:E46),LOOKUP(B45,D37:D46,F37:F46)))))&IF(SUM(B43:B45)>0," trăm","")) -> #REF! | D45: 8 | E45: Tám | F45: tám | G45: =ROUNDDOWN(G44/10,0) -> #REF!
A46: Hàng tỷ | B46: =G46-10*G47 -> #REF! | C46: =IF(G46=0,"",IF(B46=0,"",IF(AND(B46=1,B47=1)," một",IF(AND(B46=1,B47>1)," mốt",IF(AND(B46=5,B47>0)," lăm",IF(G47=0,LOOKUP(B46,D37:D46,E37:E46),LOOKUP(B46,D37:D46,F37:F46))))))&IF(SUM(B46:B52)>0," tỷ,","")) -> #REF! | D46: 9 | E46: Chín | F46: chín | G46: =ROUNDDOWN(G45/10,0) -> #REF!
A47: Hàng chục tỷ | B47: =G47-10*G48 -> #REF! | C47: =IF(G47=0,"",IF(AND(B47=0,B46=0),"",IF(AND(B47=0,B46>0)," lẻ",IF(AND(B47=1,G48<>0)," mười",IF(AND(B47=1,G48=0)," Mười",IF(B47>1,IF(G48=0,LOOKUP(B47,D37:D46,E37:E46),LOOKUP(B47,D37:D46,F37:F46)))))))&IF(B47>1," mươi","")) -> #REF! | G47: =ROUNDDOWN(G46/10,0) -> #REF!
A48: Hàng trăm tỷ | B48: =G48-10*G49 -> #REF! | C48: =IF(G48=0,"",IF(AND(B46=0,B47=0,B48=0),"",IF(AND(B48=0,B47>0)," không",IF(AND(B48=0,B46>0)," không",IF(G49=0,LOOKUP(B48,D37:D46,E37:E46),LOOKUP(B48,D37:D46,F37:F46)))))&IF(SUM(B46:B48)>0," trăm","")) -> #REF! | G48: =ROUNDDOWN(G47/10,0) -> #REF!
A49: Hàng nghìn tỷ | B49: =G49-10*G50 -> #REF! | C49: =IF(G49=0,"",IF(B49=0,"",IF(AND(B49=1,B50=1)," một",IF(AND(B49=1,B50>1)," mốt",IF(AND(B49=5,B50>0)," lăm",IF(G50=0,LOOKUP(B49,D37:D46,E37:E46),LOOKUP(B49,D37:D46,F37:F46))))))&IF(SUM(B49:B51)>0," nghìn","")) -> #REF! | G49: =ROUNDDOWN(G48/10,0) -> #REF!
A50: Hàng chục nghìn tỷ | B50: =G50-10*G51 -> #REF! | C50: =IF(G50=0,"",IF(AND(B50=0,B49=0),"",IF(AND(B50=0,B49>0)," lẻ",IF(AND(B50=1,G51<>0)," mười",IF(AND(B50=1,G51=0)," Mười",IF(B50>1,IF(G51=0,LOOKUP(B50,D37:D46,E37:E46),LOOKUP(B50,D37:D46,F37:F46)))))))&IF(B50>1," mươi","")) -> #REF! | G50: =ROUNDDOWN(G49/10,0) -> #REF!
...
