Workbook

Sheet BOQ Tổng
A1: BOQ UPS DỰ ÁN MARRIOTT
A2: STT | B2: Rack | C2: Số lượng | D2: Công suất yêu cầu (W) | E2: Thời gian lưu điện | F2: Dạng | G2: Điện áp | H2: Kết nối Modbus | I2: Ghi chú | J2: UPS cũ
A3: UPS CHO HỆ THỐNG IT
A4: 1 | B4: SERVER 4BF | C4: 2 | D4: =DC!D17 -> 15150 | E4: 30 phút | F4: Tower/Rack | G4: 3P 380V/220VAC | H4: Có
A5: 2 | B5: IDF-M.B3F | C5: 1 | D5: ='UPS CAL'!AA5 -> 119.15 | E5: 30 phút | F5: Gắn rack | G5: 220 VAC | H5: Không | I5: Kích thước không quá 14U | J5: 500
A6: 3 | B6: IDF-M.B1F | C6: 1 | D6: ='UPS CAL'!AA8 -> 740.8 | E6: 30 phút | F6: Gắn rack | G6: 220 VAC | H6: Không | I6: Kích thước không quá 14U | J6: 1000
A7: 4 | B7: IDF-M.1F | C7: 1 | D7: ='UPS CAL'!AA10 -> 1070.1 | E7: 30 phút | F7: Gắn rack | G7: 220 VAC | H7: Không | I7: Kích thước không quá 14U | J7: 1500
A8: 5 | B8: IDF-M.2F | C8: 1 | D8: ='UPS CAL'!AA11 -> 570.85 | E8: 30 phút | F8: Gắn rack | G8: 220 VAC | H8: Không | I8: Kích thước không quá 14U | J8: 1000
A9: 6 | B9: IDF-M.3F | C9: 1 | D9: ='UPS CAL'!AA12 -> 510.65 | E9: 30 phút | F9: Gắn rack | G9: 220 VAC | H9: Không | I9: Kích thước không quá 14U | J9: 1000
A10: 7 | B10: IDF-M.3AF | C10: 1 | D10: ='UPS CAL'!AA13 -> 512.3 | E10: 30 phút | F10: Gắn rack | G10: 220 VAC | H10: Không | I10: Kích thước không quá 14U | J10: 1000
A11: 8 | B11: IDF-M.4F | C11: 1 | D11: ='UPS CAL'!AA14 -> 547.4 | E11: 30 phút | F11: Gắn rack | G11: 220 VAC | H11: Không | I11: Kích thước không quá 14U | J11: 1000
A12: 9 | B12: IDF-M.4AF | C12: 1 | D12: ='UPS CAL'!AA15 -> 545.4 | E12: 30 phút | F12: Gắn rack | G12: 220 VAC | H12: Không | I12: Kích thước không quá 14U | J12: 1000
A13: 10 | B13: IDF-M.4BF | C13: 1 | D13: ='UPS CAL'!AA16 -> 1440.85 | E13: 30 phút | F13: Gắn rack | G13: 220 VAC | H13: Không | I13: Kích thước không quá 14U | J13: 1500
A14: 11 | B14: IDF-M.5F | C14: 1 | D14: ='UPS CAL'!AA17 -> 1406.25 | E14: 30 phút | F14: Gắn rack | G14: 220 VAC | H14: Không | I14: Kích thước không quá 14U | J14: 1500
A15: 12 | B15: IDF-M.7F | C15: 1 | D15: ='UPS CAL'!AA19 -> 1420.3 | E15: 30 phút | F15: Gắn rack | G15: 220 VAC | H15: Không | I15: Kích thước không quá 14U | J15: 1500
A16: 13 | B16: IDF-M.9F | C16: 1 | D16: ='UPS CAL'!AA21 -> 1420.3 | E16: 30 phút | F16: Gắn rack | G16: 220 VAC | H16: Không | I16: Kích thước không quá 14U | J16: 1500
A17: 14 | B17: IDF-M.11F | C17: 1 | D17: ='UPS CAL'!AA23 -> 1420.3 | E17: 30 phút | F17: Gắn rack | G17: 220 VAC | H17: Không | I17: Kích thước không quá 14U | J17: 1500
A18: 15 | B18: IDF-M.13F | C18: 1 | D18: ='UPS CAL'!AA25 -> 1420.3 | E18: 30 phút | F18: Gắn rack | G18: 220 VAC | H18: Không | I18: Kích thước không quá 14U | J18: 1500
A19: 16 | B19: IDF-M.15F | C19: 1 | D19: ='UPS CAL'!AA27 -> 1420.3 | E19: 30 phút | F19: Gắn rack | G19: 220 VAC | H19: Không | I19: Kích thước không quá 14U | J19: 1500
A20: 17 | B20: IDF-M.18F | C20: 0 | D20: ='UPS CAL'!AA29 -> 2104.75 | E20: 30 phút | F20: Gắn rack | G20: 220 VAC | H20: Không | I20: Kích thước không quá 14U | J20: 2500
A21: 18 | B21: IDF-M.21F | C21: 0 | D21: ='UPS CAL'!AA32 -> 2099.4 | E21: 30 phút | F21: Gắn rack | G21: 220 VAC | H21: Không | I21: Kích thước không quá 14U | J21: 2500
A22: 19 | B22: IDF-M.23F | C22: 0 | D22: ='UPS CAL'!AA35 -> 1151.85 | E22: 30 phút | F22: Gắn rack | G22: 220 VAC | H22: Không | I22: Kích thước không quá 14U | J22: 1500
A23: 20 | B23: IDF-M.39F | C23: 0 | D23: ='UPS CAL'!AA38 -> 612 | E23: 30 phút | F23: Gắn rack | G23: 220 VAC | H23: Không | I23: Kích thước không quá 14U | J23: 1000
A24: 21 | B24: IDF-A.2F | C24: 1 | D24: ='UPS CAL'!AA41 -> 174 | E24: 30 phút | F24: Gắn rack | G24: 220 VAC | H24: Không | I24: Kích thước không quá 14U | J24: 500
A25: 22 | B25: IDF-A.24AF | C25: 1 | D25: ='UPS CAL'!AA45 -> 482.1 | E25: 30 phút | F25: Gắn rack | G25: 220 VAC | H25: Không | I25: Kích thước không quá 14U | J25: 500
A26: 23 | B26: IDF-A.26F | C26: 0 | D26: ='UPS CAL'!AA47 -> 2204.7 | E26: 30 phút | F26: Gắn rack | G26: 220 VAC | H26: Không | I26: Kích thước không quá 14U | J26: 2500
A27: 24 | B27: IDF-A.29F | C27: 0 | D27: ='UPS CAL'!AA50 -> 2204.7 | E27: 30 phút | F27: Gắn rack | G27: 220 VAC | H27: Không | I27: Kích thước không quá 14U | J27: 2500
A28: 25 | B28: IDF-A.32F | C28: 0 | D28: ='UPS CAL'!AA53 -> 2204.7 | E28: 30 phút | F28: Gắn rack | G28: 220 VAC | H28: Không | I28: Kích thước không quá 14U | J28: 2500
A29: 26 | B29: IDF-A.35F | C29: 0 | D29: ='UPS CAL'!AA56 -> 2204.7 | E29: 30 phút | F29: Gắn rack | G29: 220 VAC | H29: Không | I29: Kích thước không quá 14U | J29: 2500
A30: 27 | B30: IDF-A.38F | C30: 0 | D30: ='UPS CAL'!AA59 -> 1598.65 | E30: 30 phút | F30: Gắn rack | G30: 220 VAC | H30: Không | I30: Kích thước không quá 14U | J30: 2000
A31: 28 | B31: IDF-AV.2F | C31: 1 | D31: 700 | E31: 30 phút | F31: Gắn rack | G31: 220 VAC | H31: Không | I31: Kích thước không quá 14U | J31: new
A32: 29 | B32: IDF-AV.3AF | C32: 1 | D32: 700 | E32: 30 phút | F32: Gắn rack | G32: 220 VAC | H32: Không | I32: Kích thước không quá 14U | J32: new
A33: UPS CHO HỆ THỐNG MEP
A34: 30 | B34: SERVER B1F | C34: 2 | D34: =DC!D27 -> 4250 | E34: 15 phút | F34: Tower/Rack | G34: 220 VAC | H34: Có
A35: 31 | B35: IDF-M.B3F | C35: 1 | D35: ='UPS CAL'!AM5 -> 915 | E35: 15 phút | F35: Gắn rack | G35: 220 VAC | H35: Không | I35: Kích thước không quá 8U | J35: 1000
A36: 32 | B36: IDF-M.B1F | C36: 1 | D36: ='UPS CAL'!AM8 -> 747.5 | E36: 15 phút | F36: Gắn rack | G36: 220 VAC | H36: Không | I36: Kích thước không quá 8U | J36: 1000
A37: 33 | B37: IDF-M.1F | C37: 1 | D37: ='UPS CAL'!AM10 -> 989.5 | E37: 30 phút | F37: Gắn rack | G37: 220 VAC | H37: Không | I37: Kích thước không quá 8U | J37: 1000
A38: 34 | B38: IDF-M.2F | C38: 1 | D38: ='UPS CAL'!AM11 -> 352.5 | E38: 15 phút | F38: Gắn rack | G38: 220 VAC | H38: Không | I38: Kích thước không quá 8U | J38: 500
A39: 35 | B39: IDF-M.3F | C39: 1 | D39: ='UPS CAL'!AM12 -> 375 | E39: 15 phút | F39: Gắn rack | G39: 220 VAC | H39: Không | I39: Kích thước không quá 8U | J39: 500
A40: 36 | B40: IDF-M.3AF | C40: 1 | D40: ='UPS CAL'!AM13 -> 377.5 | E40: 15 phút | F40: Gắn rack | G40: 220 VAC | H40: Không | I40: Kích thước không quá 8U | J40: 500
...

Sheet SPEC
A1: Specification
A2: UPS Online for DC
A3: Output
A4: Output Power Capacity | B4: Sheet "DC"
A5: Output Connections | B5: 380 V/220V
A6: Bypass | B6: Built-in Maintenance Bypass
A7: Output Frequency | B7: 50 Hz
A8: Input
A9: Nominal Input Voltage | B9: 400 3PH
A10: Input Frequency | B10: 50 Hz
A11: Runtime (full load) | B11: 2 hours
A12: Communications
A13: Interface Port(s) | B13: Modbus
A15: UPS Online for IT
A16: Output
A17: Output Power Capacity | B17: Sheet "UPS CAL" column AA
A18: Output Connections | B18: 220V
A19: Output Frequency | B19: 50 Hz
A20: Input
A21: Nominal Input Voltage | B21: 220v
A22: Input Frequency | B22: 50 Hz
A23: Runtime (full load) | B23: 2 hours
A24: Installation Type | B24: RACK
A25: Size | B25: < 14U
A26: UPS Online for MEP
A27: Output
A28: Output Power Capacity | B28: Sheet "UPS CAL" column AM
A29: Output Connections | B29: 220V
A30: Output Frequency | B30: 50 Hz
A31: Input
A32: Nominal Input Voltage | B32: 220 V
A33: Input Frequency | B33: 50 Hz
A34: Runtime (full load) | B34: 30 mins
A35: Installation Type | B35: RACK
A36: Size | B36: < 8U

Sheet DC
A1: UPS PHÒNG DATA CENTER IT
A3: Thiết bị | B3: Số lượng | C3: Power(W) | D3: Total(W) | E3: Ghi chú
A4: Máy chủ
A5: Máy chủ vật lý | B5: 12 | C5: 750 | D5: =C5*B5 -> 9000
A6: Máy chủ IPTV | B6: 1 | C6: 550 | D6: =C6*B6 -> 550
A7: Thiết bị KVM | B7: 1 | C7: 350 | D7: =C7*B7 -> 350
A8: Thiết bị lưu trữ
A9: Backup tape driver | B9: 1 | C9: 750 | D9: =C9*B9 -> 750
A10: San Storage | B10: 1 | C10: 750 | D10: =C10*B10 -> 750
A11: Thiết bị mạng trung tâm
A12: Thiết bị IT Core Switch | B12: 2 | C12: 750 | D12: =C12*B12 -> 1500
A13: Thiết bị Wireless Controller | B13: 2 | C13: 250 | D13: =C13*B13 -> 500
A14: Thiết bị Internet Gateway | B14: 1 | C14: 350 | D14: =C14*B14 -> 350
A15: Thiết bị Firewall | B15: 1 | C15: 700 | D15: =C15*B15 -> 700
A16: Router | B16: 2 | C16: 350 | D16: =C16*B16 -> 700 | E16: Dự phòng 10%
A17: Total | D17: =SUM(D4:D16) -> 15150 | E17: =D17*1.1 -> 16665
A19: UPS PHÒNG DATA CENTER MEP
A21: Thiết bị | B21: Số lượng | C21: Power(W) | D21: Total(W) | E21: Ghi chú
A22: Máy chủ
A23: Máy chủ ảo hóa CCTV & BMS | B23: 4 | C23: 550 | D23: =C23*B23 -> 2200
A24: Máy chủ BGM, AV | B24: 1 | C24: 550 | D24: =C24*B24 -> 550
A25: Thiết bị mạng trung tâm
A26: Thiết bị ELV Core Switch | B26: 2 | C26: 750 | D26: =C26*B26 -> 1500
A27: Total | D27: =SUM(D22:D26) -> 4250 | E27: =D27*1.1 -> 4675

Sheet UPS CAL
H1: GPNS NETWORK (lưu 2H) | AB1: MEP NETWORK(lưu 30 phút)
A2: IDF name | B2: Floor | C2: GPNS | E2: Engineer | G2: Wifi | H2: Q.ty | R2: Power | AB2: Q.ty | AE2: Power
C3: 48 | D3: 24 | E3: 48 | F3: 24 | H3: Wifi Updated | I3: Wifi for Corridor, public | J3: IP Phone | K3: Access Control | L3: Wifi for Elevator | M3: Internet Data | N3: Total PoE Port | O3: Total Port | P3: IT Switch 48port | Q3: IT Switch 24port | R3: Power WiFi (Max 9.7 W) | S3: IP Phone (Max 5.35 W) | T3: Access Control Max 5W | U3: Total PoE of Headend device (W) | W3: Power POE of Switch | X3: IT Switch 48port | Y3: IT Switch 24port | Z3: Total UPS for GPNS network (W) - 2 hours | AB3: Camera | AC3: MEP Switch 48GE | AD3: MEP Switch24GE | AE3: CAMERA Max 7,5W | AF3: Total PoE of Headend device (W) | AH3: MEP Switch 48GE 730W | AI3: MEP Switch24GE 370W | AJ3: BMS | AK3: VA | AL3: Total UPS for MEP network (W) - 30 minutes
A4: (1) | B4: (2) | H4: (3)=(4)+(7) | I4: (4) | J4: (5) | K4: (6) | L4: (7) | M4: (8) | N4: (9)=(3)+(5)+(6) | O4: (10)=(9)+(8) | P4: (11) | Q4: (12) | R4: 9.7 | S4: 5.35 | T4: 5 | X4: =980-740 -> 240 | Y4: =445-370 -> 75 | AE4: 7.5
A5: IDF-M.B3F | B5: B5 | G5: 1 | H5: =I5+L5 -> 2 | I5: 2 | J5: 1 | K5: 0 | L5: 0 | M5: 1 | N5: =H5+J5+K5 -> 3 | O5: =N5+M5 -> 4 | R5: =H5*$R$4 -> 19.4 | S5: =J5*$S$4 -> 5.35 | T5: =K5*5 -> 0 | U5: =SUM(R5:T5) -> 24.75 | V5: =SUM(U5:U7) -> 44.15 | W5: =SUM(P5:P7)*730+SUM(Q5:Q7)*370 -> 370 | X5: =P5*$X$4 -> 0 | Y5: =Q5*$Y$4 -> 0 | Z5: =U5+SUM(X5:Y5) -> 24.75 | AA5: =SUM(Z5:Z7) -> 119.15 | AB5: 10 | AE5: =AB5*7.5 -> 75 | AF5: =AE5 -> 75 | AG5: =SUM(AF5:AF7) -> 225 | AL5: =AF5+AH5+AI5+AJ5+AK5 -> 75 | AM5: =SUM(AL5:AL7) -> 915
B6: B4 | C6: 1 | E6: 1 | G6: 1 | H6: =I6+L6 -> 1 | I6: 1 | J6: 0 | K6: 0 | L6: 0 | M6: 0 | N6: =H6+J6+K6 -> 1 | O6: =N6+M6 -> 1 | R6: =H6*$R$4 -> 9.7 | S6: =J6*$S$4 -> 0 | T6: =K6*5 -> 0 | U6: =SUM(R6:T6) -> 9.7 | X6: =P6*$X$4 -> 0 | Y6: =Q6*$Y$4 -> 0 | Z6: =U6+SUM(X6:Y6) -> 9.7 | AB6: 10 | AE6: =AB6*7.5 -> 75 | AF6: =AE6 -> 75 | AL6: =AF6+AH6+AI6+AJ6+AK6 -> 75
B7: B3 | G7: 1 | H7: =I7+L7 -> 1 | I7: 1 | J7: 0 | K7: 0 | L7: 0 | M7: 0 | N7: =H7+J7+K7 -> 1 | O7: =N7+M7 -> 1 | P7: 0 | Q7: 1 | R7: =H7*$R$4 -> 9.7 | S7: =J7*$S$4 -> 0 | T7: =K7*5 -> 0 | U7: =SUM(R7:T7) -> 9.7 | X7: =P7*$X$4 -> 0 | Y7: =Q7*$Y$4 -> 75 | Z7: =U7+SUM(X7:Y7) -> 84.7 | AB7: 10 | AC7: 1 | AD7: 0 | AE7: =AB7*7.5 -> 75 | AF7: =AE7 -> 75 | AH7: =AC7*240 -> 240 | AI7: =AD7*75 -> 0 | AJ7: =150+150+150 -> 450 | AL7: =AF7+AH7+AI7+AJ7+AK7 -> 765
A8: IDF-M.B1F | B8: B2 | G8: 1 | H8: =I8+L8 -> 3 | I8: 3 | J8: 2 | K8: 0 | L8: 0 | M8: 2 | N8: =H8+J8+K8 -> 5 | O8: =N8+M8 -> 7 | R8: =H8*$R$4 -> 29.1 | S8: =J8*$S$4 -> 10.7 | T8: =K8*5 -> 0 | U8: =SUM(R8:T8) -> 39.8 | V8: =SUM(U8:U9) -> 260.8 | W8: =SUM(P8:P9)*730+SUM(Q8:Q9)*370 -> 1460 | X8: =P8*$X$4 -> 0 | Y8: =Q8*$Y$4 -> 0 | Z8: =U8+SUM(X8:Y8) -> 39.8 | AA8: =SUM(Z8:Z9) -> 740.8 | AB8: 11 | AE8: =AB8*7.5 -> 82.5 | AF8: =AE8 -> 82.5 | AG8: =SUM(AF8:AF9) -> 157.5 | AH8: =AC8*240 -> 0 | AI8: =AD8*75 -> 0 | AL8: =AF8+AH8+AI8+AJ8+AK8 -> 82.5 | AM8: =SUM(AL8:AL9) -> 747.5
B9: B1 | C9: 2 | E9: 1 | G9: 5 | H9: =I9+L9 -> 8 | I9: 8 | J9: 24 | K9: 3 | L9: 0 | M9: 28 | N9: =H9+J9+K9 -> 35 | O9: =N9+M9 -> 63 | P9: 2 | Q9: 0 | R9: =H9*$R$4 -> 77.6 | S9: =J9*$S$4 -> 128.4 | T9: =K9*5 -> 15 | U9: =SUM(R9:T9) -> 221 | X9: =P9*$X$4 -> 480 | Y9: =Q9*$Y$4 -> 0 | Z9: =U9+SUM(X9:Y9) -> 701 | AB9: 10 | AC9: 1 | AD9: 0 | AE9: =AB9*7.5 -> 75 | AF9: =AE9 -> 75 | AH9: =AC9*240 -> 240 | AI9: =AD9*75 -> 0 | AJ9: 350 | AL9: =AF9+AH9+AI9+AJ9+AK9 -> 665
A10: IDF-M.1F | B10: 1 | C10: 4 | E10: 1 | G10: 9 | H10: =I10+L10 -> 13 | I10: 13 | J10: 40 | K10: 2 | L10: 0 | M10: 64 | N10: =H10+J10+K10 -> 55 | O10: =N10+M10 -> 119 | P10: 3 | Q10: 0 | R10: =H10*$R$4 -> 126.1 | S10: =J10*$S$4 -> 214 | T10: =K10*5 -> 10 | U10: =SUM(R10:T10) -> 350.1 | V10: =U10 -> 350.1 | W10: =P10*730+Q10*370 -> 2190 | X10: =P10*$X$4 -> 720 | Y10: =Q10*$Y$4 -> 0 | Z10: =U10+SUM(X10:Y10) -> 1070.1 | AA10: =Z10 -> 1070.1 | AB10: =13+16 -> 29 | AC10: 1 | AD10: 0 | AE10: =AB10*7.5 -> 217.5 | AF10: =AE10 -> 217.5 | AG10: =AF10 -> 217.5 | AH10: =AC10*240 -> 240 | AI10: =AD10*75 -> 0 | AJ10: 200 | AK10: =132+200 -> 332 | AL10: =AF10+AH10+AI10+AJ10+AK10 -> 989.5 | AM10: =AL10 -> 989.5
A11: IDF-M.2F | B11: 2 | C11: 1 | D11: 1 | F11: 2 | G11: 11 | H11: =I11+L11 -> 17 | I11: 15 | J11: 17 | K11: 0 | L11: 2 | M11: 21 | N11: =H11+J11+K11 -> 34 | O11: =N11+M11 -> 55 | P11: 1 | Q11: 1 | R11: =H11*$R$4 -> 164.9 | S11: =J11*$S$4 -> 90.95 | T11: =K11*5 -> 0 | U11: =SUM(R11:T11) -> 255.85 | V11: =U11 -> 255.85 | W11: =P11*730+Q11*370 -> 1100 | X11: =P11*$X$4 -> 240 | Y11: =Q11*$Y$4 -> 75 | Z11: =U11+SUM(X11:Y11) -> 570.85 | AA11: =Z11 -> 570.85 | AB11: =15+2 -> 17 | AC11: 0 | AD11: 1 | AE11: =AB11*7.5 -> 127.5 | AF11: =AE11 -> 127.5 | AG11: =AF11 -> 127.5 | AH11: =AC11*240 -> 0 | AI11: =AD11*75 -> 75 | AJ11: 150 | AL11: =AF11+AH11+AI11+AJ11+AK11 -> 352.5 | AM11: =AL11 -> 352.5
A12: IDF-M.3F | B12: 3 | C12: 2 | F12: 2 | G12: 10 | H12: =I12+L12 -> 13 | I12: 13 | J12: 13 | K12: 0 | L12: 0 | M12: 22 | N12: =H12+J12+K12 -> 26 | O12: =N12+M12 -> 48 | P12: 1 | Q12: 1 | R12: =H12*$R$4 -> 126.1 | S12: =J12*$S$4 -> 69.55 | T12: =K12*5 -> 0 | U12: =SUM(R12:T12) -> 195.65 | V12: =U12 -> 195.65 | W12: =P12*730+Q12*370 -> 1100 | X12: =P12*$X$4 -> 240 | Y12: =Q12*$Y$4 -> 75 | Z12: =U12+SUM(X12:Y12) -> 510.65 | AA12: =Z12 -> 510.65 | AB12: =2+8 -> 10 | AC12: 0 | AD12: 2 | AE12: =AB12*7.5 -> 75 | AF12: =AE12 -> 75 | AG12: =AF12 -> 75 | AH12: =AC12*240 -> 0 | AI12: =AD12*75 -> 150 | AJ12: 150 | AL12: =AF12+AH12+AI12+AJ12+AK12 -> 375 | AM12: =AL12 -> 375
A13: IDF-M.3AF | B13: 3A | C13: 1 | D13: 1 | F13: 2 | G13: 10 | H13: =I13+L13 -> 11 | I13: 11 | J13: 16 | K13: 1 | L13: 0 | M13: 21 | N13: =H13+J13+K13 -> 28 | O13: =N13+M13 -> 49 | P13: 1 | Q13: 1 | R13: =H13*$R$4 -> 106.7 | S13: =J13*$S$4 -> 85.6 | T13: =K13*5 -> 5 | U13: =SUM(R13:T13) -> 197.3 | V13: =U13 -> 197.3 | W13: =P13*730+Q13*370 -> 1100 | X13: =P13*$X$4 -> 240 | Y13: =Q13*$Y$4 -> 75 | Z13: =U13+SUM(X13:Y13) -> 512.3 | AA13: =Z13 -> 512.3 | AB13: 7 | AC13: 0 | AD13: 1 | AE13: =AB13*7.5 -> 52.5 | AF13: =AE13 -> 52.5 | AG13: =AF13 -> 52.5 | AH13: =AC13*240 -> 0 | AI13: =AD13*75 -> 75 | AJ13: 250 | AL13: =AF13+AH13+AI13+AJ13+AK13 -> 377.5 | AM13: =AL13 -> 377.5
A14: IDF-M.4F | B14: 4 | C14: 1 | D14: 1 | F14: 1 | G14: 8 | H14: =I14+L14 -> 13 | I14: 13 | J14: 18 | K14: 2 | L14: 0 | M14: 25 | N14: =H14+J14+K14 -> 33 | O14: =N14+M14 -> 58 | P14: 1 | Q14: 1 | R14: =H14*$R$4 -> 126.1 | S14: =J14*$S$4 -> 96.3 | T14: =K14*5 -> 10 | U14: =SUM(R14:T14) -> 232.4 | V14: =U14 -> 232.4 | W14: =P14*730+Q14*370 -> 1100 | X14: =P14*$X$4 -> 240 | Y14: =Q14*$Y$4 -> 75 | Z14: =U14+SUM(X14:Y14) -> 547.4 | AA14: =Z14 -> 547.4 | AB14: 6 | AC14: 0 | AD14: 1 | AE14: =AB14*7.5 -> 45 | AF14: =AE14 -> 45 | AG14: =AF14 -> 45 | AH14: =AC14*240 -> 0 | AI14: =AD14*75 -> 75 | AJ14: 400 | AK14: =98+200 -> 298 | AL14: =AF14+AH14+AI14+AJ14+AK14 -> 818 | AM14: =AL14 -> 818
A15: IDF-M.4AF | B15: 4A | C15: 1 | D15: 1 | F15: 1 | G15: 11 | H15: =I15+L15 -> 15 | I15: 15 | J15: 14 | K15: 2 | L15: 0 | M15: 32 | N15: =H15+J15+K15 -> 31 | O15: =N15+M15 -> 63 | P15: 1 | Q15: 1 | R15: =H15*$R$4 -> 145.5 | S15: =J15*$S$4 -> 74.9 | T15: =K15*5 -> 10 | U15: =SUM(R15:T15) -> 230.4 | V15: =U15 -> 230.4 | W15: =P15*730+Q15*370 -> 1100 | X15: =P15*$X$4 -> 240 | Y15: =Q15*$Y$4 -> 75 | Z15: =U15+SUM(X15:Y15) -> 545.4 | AA15: =Z15 -> 545.4 | AB15: 15 | AC15: 0 | AD15: 1 | AE15: =AB15*7.5 -> 112.5 | AF15: =AE15 -> 112.5 | AG15: =AF15 -> 112.5 | AH15: =AC15*240 -> 0 | AI15: =AD15*75 -> 75 | AJ15: 300 | AL15: =AF15+AH15+AI15+AJ15+AK15 -> 487.5 | AM15: =AL15 -> 487.5
A16: IDF-M.4BF | B16: 4B | C16: 4 | F16: 1 | G16: 11 | H16: =I16+L16 -> 16 | I16: 13 | J16: 59 | K16: 2 | L16: 3 | M16: 83 | N16: =H16+J16+K16 -> 77 | O16: =N16+M16 -> 160 | P16: 4 | Q16: 0 | R16: =H16*$R$4 -> 155.2 | S16: =J16*$S$4 -> 315.65 | T16: =K16*5 -> 10 | U16: =SUM(R16:T16) -> 480.85 | V16: =U16 -> 480.85 | W16: =P16*730+Q16*370 -> 2920 | X16: =P16*$X$4 -> 960 | Y16: =Q16*$Y$4 -> 0 | Z16: =U16+SUM(X16:Y16) -> 1440.85 | AA16: =Z16 -> 1440.85 | AB16: 13 | AC16: 0 | AD16: 1 | AE16: =AB16*7.5 -> 97.5 | AF16: =AE16 -> 97.5 | AG16: =AF16 -> 97.5 | AH16: =AC16*240 -> 0 | AI16: =AD16*75 -> 75 | AJ16: 250 | AL16: =AF16+AH16+AI16+AJ16+AK16 -> 422.5 | AM16: =AL16 -> 422.5
A17: IDF-M.5F | B17: 5 | C17: 2 | F17: 1 | G17: 31 | H17: =I17+L17 -> 30 | I17: =5+25 -> 30 | J17: =25+1+1 -> 27 | K17: 5 | L17: 0 | M17: 0 | N17: =H17+K17 -> 35 | O17: =N17+M17 -> 35 | P17: 2 | Q17: 0 | R17: =H17*9.7 -> 291 | S17: =J17*5.35 -> 144.45 | T17: =K17*5 -> 25 | U17: =R17+S17+T17 -> 460.45 | V17: =U17+U18 -> 926.25 | W17: =SUM(P17:P18)*730+SUM(Q17:Q18)*370 -> 1460 | X17: =P17*$X$4 -> 480 | Y17: =Q17*$Y$4 -> 0 | Z17: =U17+SUM(X17:Y17) -> 940.45 | AA17: =SUM(Z17:Z18) -> 1406.25 | AB17: 6 | AC17: 0 | AD17: 1 | AE17: =AB17*$AE$4 -> 45 | AF17: =AE17 -> 45 | AG17: =AF17+AF18 -> 90 | AH17: =AC17*240 -> 0 | AI17: =AD17*75 -> 75 | AJ17: 150 | AL17: =AF17+AH17+AI17+AJ17+AK17 -> 270 | AM17: =AL17+AL18 -> 315
B18: 6 | G18: 31 | H18: =I18+L18 -> 30 | I18: =5+25 -> 30 | J18: =25+1+2 -> 28 | K18: 5 | L18: 0 | M18: 0 | N18: =H18+K18 -> 35 | O18: =N18+M18 -> 35 | R18: =H18*9.7 -> 291 | S18: =J18*5.35 -> 149.8 | T18: =K18*5 -> 25 | U18: =R18+S18+T18 -> 465.8 | X18: =P18*$X$4 -> 0 | Y18: =Q18*$Y$4 -> 0 | Z18: =U18+SUM(X18:Y18) -> 465.8 | AB18: 6 | AE18: =AB18*$AE$4 -> 45 | AF18: =AE18 -> 45 | AH18: =AC18*240 -> 0 | AI18: =AD18*75 -> 0 | AL18: =AF18+AH18+AI18+AJ18+AK18 -> 45
A19: IDF-M.7F | B19: 7 | C19: 2 | F19: 1 | G19: 31 | H19: =I19+L19 -> 31 | I19: =5+26 -> 31 | J19: =25+2 -> 27 | K19: 5 | L19: 0 | M19: 0 | N19: =H19+K19 -> 36 | O19: =N19+M19 -> 36 | P19: 2 | Q19: 0 | R19: =H19*9.7 -> 300.7 | S19: =J19*5.35 -> 144.45 | T19: =K19*5 -> 25 | U19: =R19+S19+T19 -> 470.15 | V19: =U19+U20 -> 940.3 | W19: =SUM(P19:P20)*730+SUM(Q19:Q20)*370 -> 1460 | X19: =P19*$X$4 -> 480 | Y19: =Q19*$Y$4 -> 0 | Z19: =U19+SUM(X19:Y19) -> 950.15 | AA19: =Z19+Z20 -> 1420.3 | AB19: 6 | AC19: 0 | AD19: 1 | AE19: =AB19*$AE$4 -> 45 | AF19: =AE19 -> 45 | AG19: =AF19+AF20 -> 90 | AH19: =AC19*240 -> 0 | AI19: =AD19*75 -> 75 | AJ19: 0 | AK19: =71+100 -> 171 | AL19: =AF19+AH19+AI19+AJ19+AK19 -> 291 | AM19: =AL19+AL20 -> 336
B20: 8 | G20: 31 | H20: =I20+L20 -> 31 | I20: =5+26 -> 31 | J20: =25+2 -> 27 | K20: 5 | L20: 0 | M20: 0 | N20: =H20+K20 -> 36 | O20: =N20+M20 -> 36 | R20: =H20*9.7 -> 300.7 | S20: =J20*5.35 -> 144.45 | T20: =K20*5 -> 25 | U20: =R20+S20+T20 -> 470.15 | X20: =P20*$X$4 -> 0 | Y20: =Q20*$Y$4 -> 0 | Z20: =U20+SUM(X20:Y20) -> 470.15 | AB20: 6 | AE20: =AB20*$AE$4 -> 45 | AF20: =AE20 -> 45 | AH20: =AC20*240 -> 0 | AI20: =AD20*75 -> 0 | AL20: =AF20+AH20+AI20+AJ20+AK20 -> 45
A21: IDF-M.9F | B21: 9 | C21: 2 | F21: 1 | G21: 31 | H21: =I21+L21 -> 31 | I21: =5+26 -> 31 | J21: =25+2 -> 27 | K21: 5 | L21: 0 | M21: 0 | N21: =H21+K21 -> 36 | O21: =N21+M21 -> 36 | P21: 2 | Q21: 0 | R21: =H21*9.7 -> 300.7 | S21: =J21*5.35 -> 144.45 | T21: =K21*5 -> 25 | U21: =R21+S21+T21 -> 470.15 | V21: =U21+U22 -> 940.3 | W21: =SUM(P21:P22)*730+SUM(Q21:Q22)*370 -> 1460 | X21: =P21*$X$4 -> 480 | Y21: =Q21*$Y$4 -> 0 | Z21: =U21+SUM(X21:Y21) -> 950.15 | AA21: =Z21+Z22 -> 1420.3 | AB21: 6 | AC21: 0 | AD21: 1 | AE21: =AB21*$AE$4 -> 45 | AF21: =AE21 -> 45 | AG21: =AF21+AF22 -> 90 | AH21: =AC21*240 -> 0 | AI21: =AD21*75 -> 75 | AJ21: 150 | AL21: =AF21+AH21+AI21+AJ21+AK21 -> 270 | AM21: =AL21+AL22 -> 315
B22: 10 | G22: 31 | H22: =I22+L22 -> 31 | I22: =5+26 -> 31 | J22: =25+2 -> 27 | K22: 5 | L22: 0 | M22: 0 | N22: =H22+K22 -> 36 | O22: =N22+M22 -> 36 | R22: =H22*9.7 -> 300.7 | S22: =J22*5.35 -> 144.45 | T22: =K22*5 -> 25 | U22: =R22+S22+T22 -> 470.15 | X22: =P22*$X$4 -> 0 | Y22: =Q22*$Y$4 -> 0 | Z22: =U22+SUM(X22:Y22) -> 470.15 | AB22: 6 | AE22: =AB22*$AE$4 -> 45 | AF22: =AE22 -> 45 | AH22: =AC22*240 -> 0 | AI22: =AD22*75 -> 0 | AL22: =AF22+AH22+AI22+AJ22+AK22 -> 45
A23: IDF-M.11F | B23: 11 | C23: 2 | F23: 1 | G23: 31 | H23: =I23+L23 -> 31 | I23: =5+26 -> 31 | J23: =25+2 -> 27 | K23: 5 | L23: 0 | M23: 0 | N23: =H23+K23 -> 36 | O23: =N23+M23 -> 36 | P23: 2 | Q23: 0 | R23: =H23*9.7 -> 300.7 | S23: =J23*5.35 -> 144.45 | T23: =K23*5 -> 25 | U23: =R23+S23+T23 -> 470.15 | V23: =U23+U24 -> 940.3 | W23: =SUM(P23:P24)*730+SUM(Q23:Q24)*370 -> 1460 | X23: =P23*$X$4 -> 480 | Y23: =Q23*$Y$4 -> 0 | Z23: =U23+SUM(X23:Y23) -> 950.15 | AA23: =Z23+Z24 -> 1420.3 | AB23: 6 | AC23: 0 | AD23: 1 | AE23: =AB23*$AE$4 -> 45 | AF23: =AE23 -> 45 | AG23: =AF23+AF24 -> 90 | AH23: =AC23*240 -> 0 | AI23: =AD23*75 -> 75 | AJ23: 150 | AL23: =AF23+AH23+AI23+AJ23+AK23 -> 270 | AM23: =AL23+AL24 -> 315
B24: 12 | G24: 31 | H24: =I24+L24 -> 31 | I24: =5+26 -> 31 | J24: =25+2 -> 27 | K24: 5 | L24: 0 | M24: 0 | N24: =H24+K24 -> 36 | O24: =N24+M24 -> 36 | R24: =H24*9.7 -> 300.7 | S24: =J24*5.35 -> 144.45 | T24: =K24*5 -> 25 | U24: =R24+S24+T24 -> 470.15 | X24: =P24*$X$4 -> 0 | Y24: =Q24*$Y$4 -> 0 | Z24: =U24+SUM(X24:Y24) -> 470.15 | AB24: 6 | AE24: =AB24*$AE$4 -> 45 | AF24: =AE24 -> 45 | AH24: =AC24*240 -> 0 | AI24: =AD24*75 -> 0 | AL24: =AF24+AH24+AI24+AJ24+AK24 -> 45
A25: IDF-M.13F | B25: 13 | C25: 2 | F25: 1 | G25: 31 | H25: =I25+L25 -> 31 | I25: =5+26 -> 31 | J25: =25+2 -> 27 | K25: 5 | L25: 0 | M25: 0 | N25: =H25+K25 -> 36 | O25: =N25+M25 -> 36 | P25: 2 | Q25: 0 | R25: =H25*9.7 -> 300.7 | S25: =J25*5.35 -> 144.45 | T25: =K25*5 -> 25 | U25: =R25+S25+T25 -> 470.15 | V25: =U25+U26 -> 940.3 | W25: =SUM(P25:P26)*730+SUM(Q25:Q26)*370 -> 1460 | X25: =P25*$X$4 -> 480 | Y25: =Q25*$Y$4 -> 0 | Z25: =U25+SUM(X25:Y25) -> 950.15 | AA25: =Z25+Z26 -> 1420.3 | AB25: 6 | AC25: 0 | AD25: 1 | AE25: =AB25*$AE$4 -> 45 | AF25: =AE25 -> 45 | AG25: =AF25+AF26 -> 90 | AH25: =AC25*240 -> 0 | AI25: =AD25*75 -> 75 | AL25: =AF25+AH25+AI25+AJ25+AK25 -> 120 | AM25: =AL25+AL26 -> 165
B26: 14 | G26: 31 | H26: =I26+L26 -> 31 | I26: =5+26 -> 31 | J26: =25+2 -> 27 | K26: 5 | L26: 0 | M26: 0 | N26: =H26+K26 -> 36 | O26: =N26+M26 -> 36 | R26: =H26*9.7 -> 300.7 | S26: =J26*5.35 -> 144.45 | T26: =K26*5 -> 25 | U26: =R26+S26+T26 -> 470.15 | X26: =P26*$X$4 -> 0 | Y26: =Q26*$Y$4 -> 0 | Z26: =U26+SUM(X26:Y26) -> 470.15 | AB26: 6 | AE26: =AB26*$AE$4 -> 45 | AF26: =AE26 -> 45 | AH26: =AC26*240 -> 0 | AI26: =AD26*75 -> 0 | AL26: =AF26+AH26+AI26+AJ26+AK26 -> 45
A27: IDF-M.15F | B27: 15 | C27: 2 | F27: 1 | G27: 31 | H27: =I27+L27 -> 31 | I27: =5+26 -> 31 | J27: =25+2 -> 27 | K27: 5 | L27: 0 | M27: 0 | N27: =H27+K27 -> 36 | O27: =N27+M27 -> 36 | P27: 2 | Q27: 0 | R27: =H27*9.7 -> 300.7 | S27: =J27*5.35 -> 144.45 | T27: =K27*5 -> 25 | U27: =R27+S27+T27 -> 470.15 | V27: =U27+U28 -> 940.3 | W27: =SUM(P27:P28)*730+SUM(Q27:Q28)*370 -> 1460 | X27: =P27*$X$4 -> 480 | Y27: =Q27*$Y$4 -> 0 | Z27: =U27+SUM(X27:Y27) -> 950.15 | AA27: =Z27+Z28 -> 1420.3 | AB27: 6 | AC27: 0 | AD27: 1 | AE27: =AB27*$AE$4 -> 45 | AF27: =AE27 -> 45 | AG27: =AF27+AF28 -> 90 | AH27: =AC27*240 -> 0 | AI27: =AD27*75 -> 75 | AJ27: 150 | AK27: =83+100 -> 183 | AL27: =AF27+AH27+AI27+AJ27+AK27 -> 453 | AM27: =AL27+AL28 -> 498
B28: 16 | G28: 31 | H28: =I28+L28 -> 31 | I28: =5+26 -> 31 | J28: =25+2 -> 27 | K28: 5 | L28: 0 | M28: 0 | N28: =H28+K28 -> 36 | O28: =N28+M28 -> 36 | R28: =H28*9.7 -> 300.7 | S28: =J28*5.35 -> 144.45 | T28: =K28*5 -> 25 | U28: =R28+S28+T28 -> 470.15 | X28: =P28*$X$4 -> 0 | Y28: =Q28*$Y$4 -> 0 | Z28: =U28+SUM(X28:Y28) -> 470.15 | AB28: 6 | AE28: =AB28*$AE$4 -> 45 | AF28: =AE28 -> 45 | AH28: =AC28*240 -> 0 | AI28: =AD28*75 -> 0 | AL28: =AF28+AH28+AI28+AJ28+AK28 -> 45
A29: IDF-M.18F | B29: 17 | G29: 30 | H29: =I29+L29 -> 31 | I29: =5+26 -> 31 | J29: =25+1+1 -> 27 | K29: 4 | L29: 0 | M29: 0 | N29: =H29+K29 -> 35 | O29: =N29+M29 -> 35 | R29: =H29*9.7 -> 300.7 | S29: =J29*5.35 -> 144.45 | T29: =K29*5 -> 20 | U29: =R29+S29+T29 -> 465.15 | V29: =SUM(U29:U31) -> 1384.75 | W29: =SUM(P29:P31)*730+SUM(Q29:Q31)*370 -> 2190 | X29: =P29*$X$4 -> 0 | Y29: =Q29*$Y$4 -> 0 | Z29: =U29+SUM(X29:Y29) -> 465.15 | AA29: =SUM(Z29:Z31) -> 2104.75 | AB29: 6 | AE29: =AB29*$AE$4 -> 45 | AF29: =AE29 -> 45 | AG29: =SUM(AF29:AF31) -> 135 | AH29: =AC29*240 -> 0 | AI29: =AD29*75 -> 0 | AL29: =AF29+AH29+AI29+AJ29+AK29 -> 45 | AM29: =SUM(AL29:AL31) -> 360
B30: 18 | C30: 3 | E30: 1 | G30: 30 | H30: =I30+L30 -> 31 | I30: =5+26 -> 31 | J30: =25+1 -> 26 | K30: 4 | L30: 0 | M30: 0 | N30: =H30+K30 -> 35 | O30: =N30+M30 -> 35 | P30: 3 | Q30: 0 | R30: =H30*9.7 -> 300.7 | S30: =J30*5.35 -> 139.1 | T30: =K30*5 -> 20 | U30: =R30+S30+T30 -> 459.8 | X30: =P30*$X$4 -> 720 | Y30: =Q30*$Y$4 -> 0 | Z30: =U30+SUM(X30:Y30) -> 1179.8 | AB30: 6 | AC30: 0 | AD30: 1 | AE30: =AB30*$AE$4 -> 45 | AF30: =AE30 -> 45 | AH30: =AC30*240 -> 0 | AI30: =AD30*75 -> 75 | AJ30: 150 | AL30: =AF30+AH30+AI30+AJ30+AK30 -> 270
B31: 19 | G31: 30 | H31: =I31+L31 -> 31 | I31: =5+26 -> 31 | J31: 26 | K31: 4 | L31: 0 | M31: 0 | N31: =H31+K31 -> 35 | O31: =N31+M31 -> 35 | R31: =H31*9.7 -> 300.7 | S31: =J31*5.35 -> 139.1 | T31: =K31*5 -> 20 | U31: =R31+S31+T31 -> 459.8 | X31: =P31*$X$4 -> 0 | Y31: =Q31*$Y$4 -> 0 | Z31: =U31+SUM(X31:Y31) -> 459.8 | AB31: 6 | AE31: =AB31*$AE$4 -> 45 | AF31: =AE31 -> 45 | AH31: =AC31*240 -> 0 | AI31: =AD31*75 -> 0 | AL31: =AF31+AH31+AI31+AJ31+AK31 -> 45
A32: IDF-M.21F | B32: 20 | G32: 30 | H32: =I32+L32 -> 31 | I32: =5+26 -> 31 | J32: 26 | K32: 4 | L32: 0 | M32: 0 | N32: =H32+K32 -> 35 | O32: =N32+M32 -> 35 | R32: =H32*9.7 -> 300.7 | S32: =J32*5.35 -> 139.1 | T32: =K32*5 -> 20 | U32: =R32+S32+T32 -> 459.8 | V32: =SUM(U32:U34) -> 1379.4 | W32: =SUM(P32:P34)*730+SUM(Q32:Q34)*370 -> 2190 | X32: =P32*$X$4 -> 0 | Y32: =Q32*$Y$4 -> 0 | Z32: =U32+SUM(X32:Y32) -> 459.8 | AA32: =SUM(Z32:Z34) -> 2099.4 | AB32: 6 | AE32: =AB32*$AE$4 -> 45 | AF32: =AE32 -> 45 | AG32: =SUM(AF32:AF34) -> 135 | AH32: =AC32*240 -> 0 | AI32: =AD32*75 -> 0 | AL32: =AF32+AH32+AI32+AJ32+AK32 -> 45 | AM32: =SUM(AL32:AL34) -> 698
B33: 21 | C33: 3 | E33: 1 | G33: 30 | H33: =I33+L33 -> 31 | I33: =5+26 -> 31 | J33: 26 | K33: 4 | L33: 0 | M33: 0 | N33: =H33+K33 -> 35 | O33: =N33+M33 -> 35 | P33: 3 | Q33: 0 | R33: =H33*9.7 -> 300.7 | S33: =J33*5.35 -> 139.1 | T33: =K33*5 -> 20 | U33: =R33+S33+T33 -> 459.8 | X33: =P33*$X$4 -> 720 | Y33: =Q33*$Y$4 -> 0 | Z33: =U33+SUM(X33:Y33) -> 1179.8 | AB33: 6 | AC33: 0 | AD33: 1 | AE33: =AB33*$AE$4 -> 45 | AF33: =AE33 -> 45 | AH33: =AC33*240 -> 0 | AI33: =AD33*75 -> 75 | AJ33: 200 | AK33: =88+200 -> 288 | AL33: =AF33+AH33+AI33+AJ33+AK33 -> 608
B34: 22 | G34: 30 | H34: =I34+L34 -> 31 | I34: =5+26 -> 31 | J34: 26 | K34: 4 | L34: 0 | M34: 0 | N34: =H34+K34 -> 35 | O34: =N34+M34 -> 35 | R34: =H34*9.7 -> 300.7 | S34: =J34*5.35 -> 139.1 | T34: =K34*5 -> 20 | U34: =R34+S34+T34 -> 459.8 | X34: =P34*$X$4 -> 0 | Y34: =Q34*$Y$4 -> 0 | Z34: =U34+SUM(X34:Y34) -> 459.8 | AB34: 6 | AE34: =AB34*$AE$4 -> 45 | AF34: =AE34 -> 45 | AH34: =AC34*240 -> 0 | AI34: =AD34*75 -> 0 | AL34: =AF34+AH34+AI34+AJ34+AK34 -> 45
A35: IDF-M.23F | B35: 23 | G35: 30 | H35: =I35+L35 -> 31 | I35: =5+26 -> 31 | J35: 26 | K35: 4 | N35: =H35+K35 -> 35 | O35: =N35+M35 -> 35 | R35: =H35*9.7 -> 300.7 | S35: =J35*5.35 -> 139.1 | T35: =K35*5 -> 20 | U35: =R35+S35+T35 -> 459.8 | V35: =SUM(U35:U37) -> 671.85 | W35: =SUM(P35:P37)*730+SUM(Q35:Q37)*370 -> 1460 | X35: =P35*$X$4 -> 0 | Y35: =Q35*$Y$4 -> 0 | Z35: =U35+SUM(X35:Y35) -> 459.8 | AA35: =SUM(Z35:Z37) -> 1151.85 | AB35: 6 | AE35: =AB35*$AE$4 -> 45 | AF35: =AE35 -> 45 | AG35: =SUM(AF35:AF37) -> 120 | AH35: =AC35*240 -> 0 | AI35: =AD35*75 -> 0 | AJ35: 250 | AL35: =AF35+AH35+AI35+AJ35+AK35 -> 295 | AM35: =SUM(AL35:AL37) -> 445
B36: 24 | C36: 3 | F36: 1 | G36: 5 | H36: =I36+L36 -> 7 | I36: 7 | J36: 7 | K36: 0 | L36: 0 | M36: 5 | N36: =H36+K36 -> 7 | O36: =N36+M36 -> 12 | P36: 2 | Q36: 0 | R36: =H36*9.7 -> 67.9 | S36: =J36*5.35 -> 37.45 | T36: =K36*5 -> 0 | U36: =R36+S36+T36 -> 105.35 | X36: =P36*$X$4 -> 480 | Y36: =Q36*$Y$4 -> 0 | Z36: =U36+SUM(X36:Y36) -> 585.35 | AB36: 2 | AC36: 0 | AD36: 1 | AE36: =AB36*$AE$4 -> 15 | AF36: =AE36 -> 15 | AH36: =AC36*240 -> 0 | AI36: =AD36*75 -> 75 | AL36: =AF36+AH36+AI36+AJ36+AK36 -> 90
B37: 24A | G37: 6 | H37: =I37+L37 -> 11 | I37: 7 | J37: 0 | K37: 0 | L37: 4 | M37: 7 | N37: =H37+K37 -> 11 | O37: =N37+M37 -> 18 | R37: =H37*9.7 -> 106.7 | S37: =J37*5.35 -> 0 | T37: =K37*5 -> 0 | U37: =R37+S37+T37 -> 106.7 | X37: =P37*$X$4 -> 0 | Y37: =Q37*$Y$4 -> 0 | Z37: =U37+SUM(X37:Y37) -> 106.7 | AB37: =4+4 -> 8 | AE37: =AB37*$AE$4 -> 60 | AF37: =AE37 -> 60 | AH37: =AC37*240 -> 0 | AI37: =AD37*75 -> 0 | AL37: =AF37+AH37+AI37+AJ37+AK37 -> 60
A38: IDF-M.39F | B38: PL | H38: =I38+L38 -> 3 | I38: 3 | J38: 3 | K38: 0 | L38: 0 | M38: 3 | N38: =H38+K38 -> 3 | O38: =N38+M38 -> 6 | R38: =H38*9.7 -> 29.1 | S38: =J38*5.35 -> 16.05 | T38: =K38*5 -> 0 | U38: =R38+S38+T38 -> 45.15 | V38: =SUM(U38:U40) -> 297 | W38: =SUM(P38:P40)*730+SUM(Q38:Q40)*370 -> 1100 | X38: =P38*$X$4 -> 0 | Y38: =Q38*$Y$4 -> 0 | Z38: =U38+SUM(X38:Y38) -> 45.15 | AA38: =SUM(Z38:Z40) -> 612 | AB38: 5 | AE38: =AB38*$AE$4 -> 37.5 | AF38: =AE38 -> 37.5 | AG38: =SUM(AF38:AF40) -> 157.5 | AH38: =AC38*240 -> 0 | AI38: =AD38*75 -> 0 | AL38: =AF38+AH38+AI38+AJ38+AK38 -> 37.5 | AM38: =SUM(AL38:AL40) -> 832.5
B39: 39 | H39: =I39+L39 -> 11 | I39: 11 | J39: 6 | K39: 0 | L39: 0 | M39: 19 | N39: =H39+K39 -> 11 | O39: =N39+M39 -> 30 | P39: 1 | Q39: 1 | R39: =H39*9.7 -> 106.7 | S39: =J39*5.35 -> 32.1 | T39: =K39*5 -> 0 | U39: =R39+S39+T39 -> 138.8 | X39: =P39*$X$4 -> 240 | Y39: =Q39*$Y$4 -> 75 | Z39: =U39+SUM(X39:Y39) -> 453.8 | AB39: 8 | AC39: 1 | AD39: 0 | AE39: =AB39*$AE$4 -> 60 | AF39: =AE39 -> 60 | AH39: =AC39*240 -> 240 | AI39: =AD39*75 -> 0 | AJ39: 300 | AK39: =35+100 -> 135 | AL39: =AF39+AH39+AI39+AJ39+AK39 -> 735
B40: RF | H40: =I40+L40 -> 10 | I40: 6 | J40: 3 | K40: 0 | L40: 4 | M40: 3 | N40: =H40+K40 -> 10 | O40: =N40+M40 -> 13 | R40: =H40*9.7 -> 97 | S40: =J40*5.35 -> 16.05 | T40: =K40*5 -> 0 | U40: =R40+S40+T40 -> 113.05 | X40: =P40*$X$4 -> 0 | Y40: =Q40*$Y$4 -> 0 | Z40: =U40+SUM(X40:Y40) -> 113.05 | AB40: 8 | AE40: =AB40*$AE$4 -> 60 | AF40: =AE40 -> 60 | AH40: =AC40*240 -> 0 | AI40: =AD40*75 -> 0 | AL40: =AF40+AH40+AI40+AJ40+AK40 -> 60
...

Sheet maximum size UPS
C4: Rack IDF
B5: 27 | C5: ODF 12F | D5: RACK IT
B6: 26 | C6: Switch 48 Ports POE
B7: 25 | C7: 1RU Cable Management
B8: 24 | C8: 48 Port RJ45 Patch Panel
B9: 23
B10: 22 | C10: Switch 48 Ports POE
B11: 21 | C11: 1RU Cable Management
B12: 20 | C12: 48 Port RJ45 Patch Panel
B13: 19
B14: 18 | C14: Switch 48 Ports POE
B15: 17 | C15: 1RU Cable Management
B16: 16 | C16: 48 Port RJ45 Patch Panel
B17: 15
B18: 14 | C18: UPS
B19: 13
B20: 12
B21: 11
B22: 10
B23: 9
B24: 8
B25: 7
B26: 6
B27: 5
B28: 4
B29: 3
B30: 2
B31: 1
B32: 15 | C32: ODF 12F | D32: RACK MEP
B33: 14 | C33: Switch 24 Ports POE
B34: 13 | C34: 1RU Cable Management
B35: 12 | C35: 24 Port RJ45 Patch Panel
B36: 11 | C36: Switch 24 Ports POE
B37: 10 | C37: 1RU Cable Management
B38: 9 | C38: 24 Port RJ45 Patch Panel
B39: 8 | C39: UPS
B40: 7
B41: 6
B42: 5
B43: 4
...
