Workbook

Sheet Networking BOQ
A1: Item | B1: Part No. | C1: Units | D1: Unit Price | F1: Part | G1: Mô tả
A2: GPNS Switch Infrastructure
A3: Core Switch
A4: Core Switch | C4: 2 | F4: J9822A | G4: Aruba 5412R zl2 Switch
A5: Stack cable | C5: 2 | F5: JH235A | G5: HPE X242 40G QSFP+ to QSFP+ 3m DAC Cable
A6: ……
A7: Access Switch
A8: 24G PoE+ 4SFP+ Switch | C8: =Detail!C55 -> 13 | F8: JL255A | G8: Aruba 2930F 24G PoE+ 4SFP+ Switch
A9: 48G PoE+ 4SFP+ Switch | C9: =Detail!B55 -> 48 | F9: JL558A | G9: Aruba 2930F 48G PoE+ 740W 4SFP+
A10: Stack cable
A11: DAC 10G
A12: 10G SFP+ to SFP+ 3m DAC Cable | C12: =Detail!G55 -> 59 | F12: J9283D | G12: Aruba 10G SFP+ to SFP+ 3m DAC Cable
A13: SFP+ 10G
A14: 10G SFP+ LC SR 300m MMF Transceiver | C14: =Detail!H58 -> 100 | F14: J9150D | G14: Aruba 10G SFP+ LC SR 300m OM3 MMF Transceiver
A15: Engineer Switch Infrastructure
A16: Core Switch
A17: Core Switch | C17: 2 | F17: J9821A | G17: Aruba 5406R zl2 Switch
A18: Stack cable | C18: 2 | F18: JH235A | G18: HPE X242 40G QSFP+ to QSFP+ 3m DAC Cable
A19: ……
A20: Access Switch
A21: 24G PoE+ 4SFP+ Switch | C21: =Detail!E55 -> 24 | F21: JL255A | G21: Aruba 2930F 24G PoE+ 4SFP+ Switch
A22: 48G PoE+ 4SFP+ Switch | C22: =Detail!D55 -> 5 | F22: JL558A | G22: Aruba 2930F 48G PoE+ 740W 4SFP+
A23: Stack cable
A24: DAC 10G
A25: 10G SFP+ to SFP+ 3m DAC Cable | C25: =Detail!I55 -> 7 | F25: J9283D | G25: Aruba 10G SFP+ to SFP+ 3m DAC Cable
A26: SFP+ 10G
A27: 10G SFP+ LC SR 300m MMF Transceiver | C27: =Detail!J58 -> 100 | F27: J9150D | G27: Aruba 10G SFP+ LC SR 300m OM3 MMF Transceiver
A28: Wireless Infrastructure
A29: Wireless Controller | C29: 2 | F29: JW783A | G29: Aruba 7240XM (RW) 4p 10GBase-X (SFP+) 2p Dual Pers (10/100/1000BASE-T or SFP) Controller
A30: ……
A31: Guest Room Wireless | C31: =487+392 -> 879 | E31: AP will be connected to TV and Telephone (POE) | F31: JY678A | G31: Aruba AP-303H (RW) Unified AP
A32: Guest Corridor Wireless | C32: =95+65 -> 160 | F32: JZ320A | G32: Aruba AP-303 (RW) Unified AP
A33: Public Area Wireless | C33: 112 | F33: JX936A | G33: Aruba AP-305 802.11n/ac 2x2:2/3x3:3 MU-MIMO Dual Radio Integrated Antenna AP
A34: BOH Wireless | C34: =15+5 -> 20 | F34: JZ320A | G34: Aruba AP-303 (RW) Unified AP
A35: Conference Area Wireless | C35: 14 | F35: JZ031A | G35: Aruba AP-345 (RW) Unified AP
A36: Elevator Wireless | C36: =13+4 -> 17 | E36: +17 Convert RG6 to Cat6 | F36: JZ320A | G36: Aruba AP-303 (RW) Unified AP
G37: Planet VC-232G 1-Port 10/100/1000T Ethernet over Coaxial Converter
A38: Outdoor Wireless | C38: 3 | F38: JX966A | G38: Aruba AP-365 (RW) Outdoor AP
A39: Heat Map Test (AirMagnet Survey wireless) | C39: 1
A40: Test & Commission | C40: 1
...

Sheet Accessory
A1: Item | B1: Part No. | C1: Units | D1: Unit Price | E1: Total | F1: Note
A2: Rack
A3: RACK 42U 800x1000 | C3: 6 | F3: Vietrack
A4: RACK 42U 600x800 | C4: =Detail!L55 -> 24 | F4: Vietrack
A5: Path Panel
A6: Patch Panel 24 | C6: =Detail!N55 -> 37 | F6: Belden
A7: Patch Panel 48 | C7: =Detail!O55 -> 53 | F7: Belden
A8: Cab Mgmt | C8: =Detail!S59 -> 94 | F8: Vietrack
A9: Patch Cord | C9: =Detail!Q55 -> 3432 | F9: Belden
A10: Fiber Accessory
A11: ODF 12 | C11: =Detail!M55 -> 24 | F11: Belden
A12: ODF 48 | C12: =Detail!M59 -> 6 | F12: Belden
A13: Adapters Strip, 6 Port SC Duplex (12F) MM | C13: 54 | F13: Belden
A14: Fiber Patch Cord LC/SC OM3 | C14: =Detail!P58 -> 200 | F14: Belden
A15: Pigtail SC OM3 Simplex | C15: =Detail!P59 -> 400 | F15: Belden
A16: PDU
A17: PDU 24 | C17: =Detail!T59 -> 60 | F17: APC

Sheet Detail
A1: Floor | B1: GPNS | D1: Engineer | F1: Wifi | G1: GPNS | I1: Engineer | K1: Data | L1: Rack 42U (600x800) | M1: ODF 12 | N1: PP24 | O1: PP48 | P1: Fiber PC | Q1: Copper PC | R1: Adapters Strip, 6 Port SC Duplex (12F) MM | S1: Cab Mgmt | T1: PDU 24
B2: 48 | C2: 24 | D2: 48 | E2: 24 | G2: DAC 10G | H2: SFP+ | I2: DAC 10G | J2: SFP+ | M2: ODF 12 | N2: ODF 24
A3: B5
A4: B4 | C4: 1 | D4: 1 | H4: 2 | J4: 2 | L4: 1 | M4: 1 | N4: =C4+E4 -> 1 | O4: =D4+B4 -> 1 | P4: =J4+H4 -> 4 | Q4: =B4*48+C4*24+D4*48+E4*24 -> 72 | R4: =L4*2 -> 2 | S4: =SUM(B4:E4) -> 2 | T4: =L4*2 -> 2
A5: B3 | N5: =C5+E5 -> 0 | O5: =D5+B5 -> 0 | P5: =J5+H5 -> 0 | Q5: =B5*48+C5*24+D5*48+E5*24 -> 0 | R5: =L5*2 -> 0 | S5: =SUM(B5:E5) -> 0 | T5: =L5*2 -> 0
A6: B2 | N6: =C6+E6 -> 0 | O6: =D6+B6 -> 0 | P6: =J6+H6 -> 0 | Q6: =B6*48+C6*24+D6*48+E6*24 -> 0 | R6: =L6*2 -> 0 | S6: =SUM(B6:E6) -> 0 | T6: =L6*2 -> 0
A7: B1 | B7: 1 | C7: 1 | D7: 1 | G7: 2 | H7: 2 | J7: 2 | L7: 1 | M7: 1 | N7: =C7+E7 -> 1 | O7: =D7+B7 -> 2 | P7: =J7+H7 -> 4 | Q7: =B7*48+C7*24+D7*48+E7*24 -> 120 | R7: =L7*2 -> 2 | S7: =SUM(B7:E7) -> 3 | T7: =L7*2 -> 2
A8: B1A | N8: =C8+E8 -> 0 | O8: =D8+B8 -> 0 | P8: =J8+H8 -> 0 | Q8: =B8*48+C8*24+D8*48+E8*24 -> 0 | R8: =L8*2 -> 0 | S8: =SUM(B8:E8) -> 0 | T8: =L8*2 -> 0
A9: 1 | B9: 3 | D9: 1 | G9: 3 | H9: 2 | J9: 2 | L9: 1 | M9: 1 | N9: =C9+E9 -> 0 | O9: =D9+B9 -> 4 | P9: =J9+H9 -> 4 | Q9: =B9*48+C9*24+D9*48+E9*24 -> 192 | R9: =L9*2 -> 2 | S9: =SUM(B9:E9) -> 4 | T9: =L9*2 -> 2
A10: 2 | B10: 1 | C10: 1 | D10: 1 | E10: 2 | G10: 2 | H10: 2 | I10: 3 | J10: 2 | L10: 1 | M10: 1 | N10: =C10+E10 -> 3 | O10: =D10+B10 -> 2 | P10: =J10+H10 -> 4 | Q10: =B10*48+C10*24+D10*48+E10*24 -> 168 | R10: =L10*2 -> 2 | S10: =SUM(B10:E10) -> 5 | T10: =L10*2 -> 2
A11: 3 | B11: 1 | C11: 1 | E11: 2 | G11: 2 | H11: 2 | I11: 2 | J11: 2 | L11: 1 | M11: 1 | N11: =C11+E11 -> 3 | O11: =D11+B11 -> 1 | P11: =J11+H11 -> 4 | Q11: =B11*48+C11*24+D11*48+E11*24 -> 120 | R11: =L11*2 -> 2 | S11: =SUM(B11:E11) -> 4 | T11: =L11*2 -> 2
A12: 3A | B12: 1 | C12: 1 | E12: 2 | G12: 2 | H12: 2 | I12: 2 | J12: 2 | L12: 1 | M12: 1 | N12: =C12+E12 -> 3 | O12: =D12+B12 -> 1 | P12: =J12+H12 -> 4 | Q12: =B12*48+C12*24+D12*48+E12*24 -> 120 | R12: =L12*2 -> 2 | S12: =SUM(B12:E12) -> 4 | T12: =L12*2 -> 2
A13: 4 | B13: 1 | C13: 1 | E13: 1 | G13: 2 | H13: 2 | J13: 2 | L13: 1 | M13: 1 | N13: =C13+E13 -> 2 | O13: =D13+B13 -> 1 | P13: =J13+H13 -> 4 | Q13: =B13*48+C13*24+D13*48+E13*24 -> 96 | R13: =L13*2 -> 2 | S13: =SUM(B13:E13) -> 3 | T13: =L13*2 -> 2
A14: 4A | B14: 1 | C14: 1 | E14: 1 | G14: 2 | H14: 2 | J14: 2 | L14: 1 | M14: 1 | N14: =C14+E14 -> 2 | O14: =D14+B14 -> 1 | P14: =J14+H14 -> 4 | Q14: =B14*48+C14*24+D14*48+E14*24 -> 96 | R14: =L14*2 -> 2 | S14: =SUM(B14:E14) -> 3 | T14: =L14*2 -> 2
A15: 4B | B15: 4 | E15: 1 | G15: 4 | H15: 2 | J15: 2 | L15: 1 | M15: 1 | N15: =C15+E15 -> 1 | O15: =D15+B15 -> 4 | P15: =J15+H15 -> 4 | Q15: =B15*48+C15*24+D15*48+E15*24 -> 216 | R15: =L15*2 -> 2 | S15: =SUM(B15:E15) -> 5 | T15: =L15*2 -> 2
A16: 5 | B16: 2 | E16: 1 | G16: 2 | H16: 2 | J16: 2 | L16: 1 | M16: 1 | N16: =C16+E16 -> 1 | O16: =D16+B16 -> 2 | P16: =J16+H16 -> 4 | Q16: =B16*48+C16*24+D16*48+E16*24 -> 120 | R16: =L16*2 -> 2 | S16: =SUM(B16:E16) -> 3 | T16: =L16*2 -> 2
A17: 6 | N17: =C17+E17 -> 0 | O17: =D17+B17 -> 0 | P17: =J17+H17 -> 0 | Q17: =B17*48+C17*24+D17*48+E17*24 -> 0 | R17: =L17*2 -> 0 | S17: =SUM(B17:E17) -> 0 | T17: =L17*2 -> 0
A18: 7 | B18: 2 | E18: 1 | G18: 2 | H18: 2 | J18: 2 | L18: 1 | M18: 1 | N18: =C18+E18 -> 1 | O18: =D18+B18 -> 2 | P18: =J18+H18 -> 4 | Q18: =B18*48+C18*24+D18*48+E18*24 -> 120 | R18: =L18*2 -> 2 | S18: =SUM(B18:E18) -> 3 | T18: =L18*2 -> 2
A19: 8 | N19: =C19+E19 -> 0 | O19: =D19+B19 -> 0 | P19: =J19+H19 -> 0 | Q19: =B19*48+C19*24+D19*48+E19*24 -> 0 | R19: =L19*2 -> 0 | S19: =SUM(B19:E19) -> 0 | T19: =L19*2 -> 0
A20: 9 | B20: 2 | E20: 1 | G20: 2 | H20: 2 | J20: 2 | L20: 1 | M20: 1 | N20: =C20+E20 -> 1 | O20: =D20+B20 -> 2 | P20: =J20+H20 -> 4 | Q20: =B20*48+C20*24+D20*48+E20*24 -> 120 | R20: =L20*2 -> 2 | S20: =SUM(B20:E20) -> 3 | T20: =L20*2 -> 2
A21: 10 | N21: =C21+E21 -> 0 | O21: =D21+B21 -> 0 | P21: =J21+H21 -> 0 | Q21: =B21*48+C21*24+D21*48+E21*24 -> 0 | R21: =L21*2 -> 0 | S21: =SUM(B21:E21) -> 0 | T21: =L21*2 -> 0
A22: 11 | B22: 2 | E22: 1 | G22: 2 | H22: 2 | J22: 2 | L22: 1 | M22: 1 | N22: =C22+E22 -> 1 | O22: =D22+B22 -> 2 | P22: =J22+H22 -> 4 | Q22: =B22*48+C22*24+D22*48+E22*24 -> 120 | R22: =L22*2 -> 2 | S22: =SUM(B22:E22) -> 3 | T22: =L22*2 -> 2
A23: 12 | N23: =C23+E23 -> 0 | O23: =D23+B23 -> 0 | P23: =J23+H23 -> 0 | Q23: =B23*48+C23*24+D23*48+E23*24 -> 0 | R23: =L23*2 -> 0 | S23: =SUM(B23:E23) -> 0 | T23: =L23*2 -> 0
A24: 13 | B24: 2 | E24: 1 | G24: 2 | H24: 2 | J24: 2 | L24: 1 | M24: 1 | N24: =C24+E24 -> 1 | O24: =D24+B24 -> 2 | P24: =J24+H24 -> 4 | Q24: =B24*48+C24*24+D24*48+E24*24 -> 120 | R24: =L24*2 -> 2 | S24: =SUM(B24:E24) -> 3 | T24: =L24*2 -> 2
A25: 14 | N25: =C25+E25 -> 0 | O25: =D25+B25 -> 0 | P25: =J25+H25 -> 0 | Q25: =B25*48+C25*24+D25*48+E25*24 -> 0 | R25: =L25*2 -> 0 | S25: =SUM(B25:E25) -> 0 | T25: =L25*2 -> 0
A26: 15 | B26: 2 | E26: 1 | G26: 2 | H26: 2 | J26: 2 | L26: 1 | M26: 1 | N26: =C26+E26 -> 1 | O26: =D26+B26 -> 2 | P26: =J26+H26 -> 4 | Q26: =B26*48+C26*24+D26*48+E26*24 -> 120 | R26: =L26*2 -> 2 | S26: =SUM(B26:E26) -> 3 | T26: =L26*2 -> 2
A27: 16 | N27: =C27+E27 -> 0 | O27: =D27+B27 -> 0 | P27: =J27+H27 -> 0 | Q27: =B27*48+C27*24+D27*48+E27*24 -> 0 | R27: =L27*2 -> 0 | S27: =SUM(B27:E27) -> 0 | T27: =L27*2 -> 0
A28: 17 | N28: =C28+E28 -> 0 | O28: =D28+B28 -> 0 | P28: =J28+H28 -> 0 | Q28: =B28*48+C28*24+D28*48+E28*24 -> 0 | R28: =L28*2 -> 0 | S28: =SUM(B28:E28) -> 0 | T28: =L28*2 -> 0
A29: 18 | B29: 3 | E29: 1 | G29: 3 | H29: 2 | J29: 2 | L29: 1 | M29: 1 | N29: =C29+E29 -> 1 | O29: =D29+B29 -> 3 | P29: =J29+H29 -> 4 | Q29: =B29*48+C29*24+D29*48+E29*24 -> 168 | R29: =L29*2 -> 2 | S29: =SUM(B29:E29) -> 4 | T29: =L29*2 -> 2
A30: 19 | N30: =C30+E30 -> 0 | O30: =D30+B30 -> 0 | P30: =J30+H30 -> 0 | Q30: =B30*48+C30*24+D30*48+E30*24 -> 0 | R30: =L30*2 -> 0 | S30: =SUM(B30:E30) -> 0 | T30: =L30*2 -> 0
A31: 20 | N31: =C31+E31 -> 0 | O31: =D31+B31 -> 0 | P31: =J31+H31 -> 0 | Q31: =B31*48+C31*24+D31*48+E31*24 -> 0 | R31: =L31*2 -> 0 | S31: =SUM(B31:E31) -> 0 | T31: =L31*2 -> 0
A32: 21 | B32: 3 | E32: 1 | G32: 3 | H32: 2 | J32: 2 | L32: 1 | M32: 1 | N32: =C32+E32 -> 1 | O32: =D32+B32 -> 3 | P32: =J32+H32 -> 4 | Q32: =B32*48+C32*24+D32*48+E32*24 -> 168 | R32: =L32*2 -> 2 | S32: =SUM(B32:E32) -> 4 | T32: =L32*2 -> 2
A33: 22 | N33: =C33+E33 -> 0 | O33: =D33+B33 -> 0 | P33: =J33+H33 -> 0 | Q33: =B33*48+C33*24+D33*48+E33*24 -> 0 | R33: =L33*2 -> 0 | S33: =SUM(B33:E33) -> 0 | T33: =L33*2 -> 0
A34: 23 | B34: 1 | E34: 1 | G34: 1 | H34: 2 | J34: 2 | N34: =C34+E34 -> 1 | O34: =D34+B34 -> 1 | P34: =J34+H34 -> 4 | Q34: =B34*48+C34*24+D34*48+E34*24 -> 72 | R34: =L34*2 -> 0 | S34: =SUM(B34:E34) -> 2 | T34: =L34*2 -> 0
A35: 24
A36: 24A | B36: 1 | E36: 1 | H36: 2 | J36: 2 | L36: 1 | M36: 1 | N36: =C36+E36 -> 1 | O36: =D36+B36 -> 1 | P36: =J36+H36 -> 4 | Q36: =B36*48+C36*24+D36*48+E36*24 -> 72 | R36: =L36*2 -> 2 | S36: =SUM(B36:E36) -> 2 | T36: =L36*2 -> 2
A37: 25
A38: 26 | B38: 3 | C38: 1 | E38: 1 | G38: 4 | H38: 2 | J38: 2 | L38: 1 | M38: 1 | N38: =C38+E38 -> 2 | O38: =D38+B38 -> 3 | P38: =J38+H38 -> 4 | Q38: =B38*48+C38*24+D38*48+E38*24 -> 192 | R38: =L38*2 -> 2 | S38: =SUM(B38:E38) -> 5 | T38: =L38*2 -> 2
A39: 27
A40: 28
...

Sheet Apartment
A1: Floor | B1: Switch | D1: Wifi | E1: Data | F1: Rack 42U
B2: 48 | C2: 24
A3: B5
A4: B4
A5: B3
A6: B2
A7: B1
A8: B1A
A9: 1
A10: 2 | B10: 1 | D10: 2
A11: 3
A12: 3A
A13: 4
A14: 4A
A15: 4B
A16: 5
A17: 6
A18: 7
A19: 8
A20: 9
A21: 10
A22: 11
A23: 12
A24: 13
A25: 14
A26: 15
A27: 16
... A34: 23
A35: 24 | B35: 1 | D35: 2
A36: 24A
A37: 25 | D37: 2
A38: 26 | B38: 2 | C38: 1 | D38: 2
A39: 27 | D39: 2
A40: 28 | D40: 2
A41: 29 | B41: 2 | C41: 1 | D41: 2
A42: 30 | D42: 2
A43: 31 | D43: 2
A44: 32 | B44: 2 | C44: 1 | D44: 2
A45: 33 | D45: 2
A46: 34 | D46: 2
...

Sheet GPON
A1: Floor | B1: ONT | C1: ODF 48 | D1: ODF 48 (Khong Coupler) | E1: ODF 24 | F1: Moi han x 6
A2: B5
A3: B4
A4: B3
A5: B2
A6: B1
A7: B1A
A8: 1
A9: 2
A10: 3
A11: 3A
A12: 4
A13: 4A
A14: 4B
A15: 5
A16: 6
A17: 7
A18: 8
A19: 9
A20: 10
A21: 11
A22: 12
A23: 13
A24: 14
A25: 15
A26: 16
A27: 17 | B27: 13 | F27: =B27*6 -> 78
A28: 18 | B28: 13 | D28: 1 | F28: =B28*6 -> 78
A29: 19 | B29: 13 | F29: =B29*6 -> 78
A30: 20 | B30: 13 | F30: =B30*6 -> 78
A31: 21 | B31: 13 | D31: 1 | F31: =B31*6 -> 78
A32: 22 | B32: 13 | F32: =B32*6 -> 78
A33: 23 | B33: 13 | F33: =B33*6 -> 78
A34: 24 | F34: =B34*6 -> 0
A35: 24A | F35: =B35*6 -> 0
A36: 25 | B36: 16 | F36: =B36*6 -> 96
A37: 26 | B37: 16 | D37: 1 | F37: =B37*6 -> 96
A38: 27 | B38: 16 | F38: =B38*6 -> 96
A39: 28 | B39: 16 | F39: =B39*6 -> 96
A40: 29 | B40: 16 | D40: 1 | F40: =B40*6 -> 96
...

Sheet Trang_tính1
E15: ggggg
