Workbook
Name Document_array: {"Book1"}
Name DSTD_Clear: [0]!DSTD_Clear

Sheet CCTV
B1: SUNTORY PEPSI LONG AN PROJECT - ME WORKS | G1: core SM | H1: core MM | J1: Rack Unit
B2: STT | C2: ITEMS | D2: UNIT | E2: Qty | F2: Used for | G2: Power Consumption | H2: REMARK
A3: 0 | C3: IDF SECURITY ROOM | D3: set | E3: 1 | G3: 224 | H3: 0 | J3: =SUBTOTAL(9,J9:J38) -> 35 | K3: COO | L3: Delivery time | M3: Brand Name | N3: UOM | O3: Price | P3: sum
C4: CABINET | D4: set | E4: 1
B5: VRS48-8120 | C5: VRS42-8120 : Tủ chứa máy chủ dòng S, 42U, 800mm x 1200mm, màu đen | E5: 1 | K5: VN | L5: 4 tuần | M5: Vietrack | N5: Cái | O5: =VLOOKUP($B5,BOM!$A$2:$K$94,10,0) -> 0 | P5: =O5*E5 -> 0
B6: VRMV48-1F | C6: VRMV48-1F : Thanh quản lý cáp dọc, 48U, dạng đơn, màu đen | E6: 2 | K6: VN | L6: 4 tuần | M6: Vietrack | N6: Cái | O6: =VLOOKUP($B6,BOM!$A$2:$K$94,10,0) -> 0 | P6: =O6*E6 -> 0
B7: VRP124-MCB32 | C7: Rack Power Distribution Unit, 24 Universal Outlets, 32A, 250V, MCB | D7: CN | E7: 2 | K7: CN | L7: 8 tuần | M7: Vietrack | N7: Cái | O7: =VLOOKUP($B7,BOM!$A$2:$K$94,10,0) -> 0 | P7: =O7*E7 -> 0
C8: ODF | D8: set | E8: 1 | G8: =ROUNDUP(G3/24,0) -> 10 | H8: =ROUNDUP(H3/24,0) -> 0 | O8: =VLOOKUP($B8,BOM!$A$2:$K$94,10,0) -> 0 | P8: =O8*E8 -> 0
B9: 760249997 | C9: EPX-1U-PNL-ENC | D9: Cái | E9: =ROUNDUP((E11+E15)/3,0) -> 4 | J9: =E9 -> 4 | K9: CN | L9: 8 tuần | M9: Commscope | N9: Cái | O9: =VLOOKUP($B9,BOM!$A$2:$K$94,10,0) -> 0 | P9: =O9*E9 -> 0
B10: 760241378 | C10: CommScope® 48 Fibers Slicing Tray Kit | D10: Cái | E10: =IF(E11<=2,1,ROUNDUP(E9*1.5,0)) -> 6 | K10: CN | L10: 8 tuần | M10: Commscope | N10: Cái | O10: =VLOOKUP($B10,BOM!$A$2:$K$94,10,0) -> 0 | P10: =O10*E10 -> 0
B11: EK5809-001 | C11: CommScope® 1000-type Adapter Plate 12 LC/UPC Duplex SM, Blue | D11: Cái | E11: =G8 -> 10 | K11: CN | L11: 8 tuần | M11: Commscope | N11: Cái | O11: =VLOOKUP($B11,BOM!$A$2:$K$94,10,0) -> 0 | P11: =O11*E11 -> 0
B12: EM2454-001 | C12: ADAPTER PLATE BLANK ASSY | D12: Cái | E12: =E9*3-E11-E15 -> 2 | K12: CN | L12: 8 tuần | M12: Commscope | N12: Cái | O12: =VLOOKUP($B12,BOM!$A$2:$K$94,10,0) -> 0 | P12: =O12*E12 -> 0
B13: 2105081-2 | C13: LC TO LC 0.9mm SM LSZH 2M | D13: sợi | E13: =G3/2 -> 112 | K13: CN | L13: 8 tuần | M13: Commscope | N13: Sợi | O13: =VLOOKUP($B13,BOM!$A$2:$K$94,10,0) -> 0 | P13: =O13*E13 -> 0
B14: 2105028-3 | C14: COMMSCOPE/ AMP Fiber Optic Cable Assembly, Duplex LC, OS2, 3m | D14: sợi | E14: =ROUNDUP(SUM(E24:E25,E29)*1.3,0) -> 56 | K14: CN | L14: 8 tuần | M14: Commscope | N14: Sợi | O14: =VLOOKUP($B14,BOM!$A$2:$K$94,10,0) -> 0 | P14: =O14*E14 -> 0
B15: EK5808-001 | C15: ADAPTER PLATE ASSY 12 LC DUP AQUA | D15: Cái | E15: =H8 -> 0 | K15: CN | L15: 8 tuần | M15: Commscope | N15: Sợi | O15: =VLOOKUP($B15,BOM!$A$2:$K$94,10,0) -> 0 | P15: =O15*E15 -> 0
B16: 2105061-3 | C16: LC TO LC 1.8mm OM4 DPX LSZH AND OFNR 3M | D16: sợi | E16: 0 | K16: CN | L16: 8 tuần | M16: Commscope | N16: Sợi | O16: =VLOOKUP($B16,BOM!$A$2:$K$94,10,0) -> 0 | P16: =O16*E16 -> 0
B17: 2105084-2 | C17: LC TO LC 0.9mm OM4 LSZH 2M | D17: sợi | E17: =H3/2 -> 0 | K17: CN | L17: 8 tuần | M17: Commscope | N17: Sợi | O17: =VLOOKUP($B17,BOM!$A$2:$K$94,10,0) -> 0 | P17: =O17*E17 -> 0
C18: Patch panel | D18: set | O18: =VLOOKUP($B18,BOM!$A$2:$K$94,10,0) -> 0 | P18: =O18*E18 -> 0
B19: 760237046 | C19: CPP-SDDM-SL-1U-24: CommScope® SL DDM Patch Panel, STP, 1U, 24 port, Straight, Unload | D19: Cái | E19: =E23+E28 -> 6 | J19: =E19 -> 6 | K19: CN | L19: 8 tuần | M19: Commscope | N19: Cái | O19: =VLOOKUP($B19,BOM!$A$2:$K$94,10,0) -> 0 | P19: =O19*E19 -> 0
B20: VRMH01-1F | C20: Horizontal Cable Management 1U, Finger Duct, Black | D20: Cái | E20: =E19 -> 6 | J20: =E20 -> 6 | K20: CN | L20: 8 tuần | M20: Vietrack | N20: Cái | O20: =VLOOKUP($B20,BOM!$A$2:$K$94,10,0) -> 0 | P20: =O20*E20 -> 0
B21: 2153449-2 | C21: NetConnect® SLX Jack, Category 6A, S/FTP, without Dust Cover, Black | D21: Cái | E21: =E19*24 -> 144 | K21: MX | L21: 8 tuần | M21: Commscope | N21: Cái | O21: =VLOOKUP($B21,BOM!$A$2:$K$94,10,0) -> 0 | P21: =O21*E21 -> 0
C22: Security Core Switch 24 port | D22: set | E22: 2 | O22: =VLOOKUP($B22,BOM!$A$2:$K$94,10,0) -> 0 | P22: =O22*E22 -> 0
B23: OS6860N-U28 | C23: OmniSwitch OS6860N-U28 Thiết bị chuyển mạch Alcatel-Lucent OmniSwitch OS6860N-U28: Fixed-configuration chassis in a 1U form factor with 24x100/1000 Base-X SFP ports, 4x 1G/10G SFP+ ports, four SFP28 (1G/10G/25G) ports and 2 x 100G QSFP28 Virtual Chassis link ports. All ports are MACSec capable. The bundle includes one system AC power supply, country-specific power cord, user manuals, access card, hardware for mounting in a 19” rack and a micro-USB-to-USB console adapter 2x Alcatel-Lucent Cable OS6860-CBL-100 1m OS6865 20 Gigabit direct attached copper cable (1m, QSFP+). | D23: cái | E23: 2 | J23: =E23 -> 2 | K23: Asia | L23: 6-8 tuần | M23: Alcatel Lucent | N23: cái | O23: =VLOOKUP($B23,BOM!$A$2:$K$94,10,0) -> 0 | P23: =O23*E23 -> 0
B24: SFP-GIG-LX | C24: Module quang SFP-GIG-LX 1000Base-LX 1310nm 20km - Alcatel-Lucent | D24: cái | E24: 37 | K24: Asia | L24: 6-8 tuần | M24: Alcatel Lucent | N24: cái | O24: =VLOOKUP($B24,BOM!$A$2:$K$94,10,0) -> 0 | P24: =O24*E24 -> 0
B25: SFP-10G-LR | C25: 10 Gigabit optical transceiver SFP+). Supports monomode fiber over 1310nm wavelength nominal) with an LC connector. Typical reach of 10Km | D25: cái | E25: 2 | K25: Asia | L25: 6-8 tuần | M25: Alcatel Lucent | N25: cái | O25: =VLOOKUP($B25,BOM!$A$2:$K$94,10,0) -> 0 | P25: =O25*E25 -> 0
B26: S2P31A | C26: HPE Aruba Networking 10G SFP+ LC LR 10km SMF C-class Transceiver | D26: cái | E26: 0 | K26: Asia | L26: 6-8 tuần | M26: HPE Aruba | N26: cái | O26: =VLOOKUP($B26,BOM!$A$2:$K$94,10,0) -> 0 | P26: =O26*E26 -> 0
C27: Switch POE 24 Ports for CCTV | D27: set | E27: 3 | I27: CCTV | O27: =VLOOKUP($B27,BOM!$A$2:$K$94,10,0) -> 0 | P27: =O27*E27 -> 0
B28: OS6360-PH24 | C28: OmniSwitch OS6360-PH24 Alcatel-Lucent OmniSwitch OS6360-PH24 Stackable Switch : Fixed 1RU chassis 24 RJ-45 PoE 10/100/1G BaseT, 2 1G* RJ45/SFP combo, 2 SFP+ (1G/10G) uplink or VFL ports. 380W power budget. *10G license upgradeable. | D28: cái | E28: 4 | J28: =E28 -> 4 | K28: Asia | L28: 6-8 tuần | M28: Alcatel Lucent | N28: cái | O28: =VLOOKUP($B28,BOM!$A$2:$K$94,10,0) -> 0 | P28: =O28*E28 -> 0
B29: SFP-GIG-LX | C29: Module quang SFP-GIG-LX 1000Base-LX 1310nm 20km - Alcatel-Lucent | D29: cái | E29: =E28 -> 4 | K29: Asia | L29: 6-8 tuần | M29: Alcatel Lucent | N29: cái | O29: =VLOOKUP($B29,BOM!$A$2:$K$94,10,0) -> 0 | P29: =O29*E29 -> 0
C30: IP AMPLIFIER (240W) | D30: set | E30: 1 | H30: Equipment by PA Supplier | J30: =E30 -> 1 | O30: =VLOOKUP($B30,BOM!$A$2:$K$94,10,0) -> 0 | P30: =O30*E30 -> 0
C31: Network Module | D31: set | E31: 1 | G31: Pulic Address | H31: Equipment by PA Supplier | J31: 1 | O31: =VLOOKUP($B31,BOM!$A$2:$K$94,10,0) -> 0 | P31: =O31*E31 -> 0
C32: Network Audio Interface Unit | D32: set | E32: 1 | G32: Pulic Address | H32: Equipment by PA Supplier | J32: =E32 -> 1 | O32: =VLOOKUP($B32,BOM!$A$2:$K$94,10,0) -> 0 | P32: =O32*E32 -> 0
C33: IP-1000CI TOA (32 ports) | D33: set | E33: 1 | H33: Equipment by PA Supplier | J33: =E33 -> 1 | O33: =VLOOKUP($B33,BOM!$A$2:$K$94,10,0) -> 0 | P33: =O33*E33 -> 0
C34: IP -GATEWAY | D34: set | E34: 1 | H34: Equipment by PA Supplier | J34: =E34 -> 1 | O34: =VLOOKUP($B34,BOM!$A$2:$K$94,10,0) -> 0 | P34: =O34*E34 -> 0
C35: Storage sever 1~6 | D35: set | E35: 1 | H35: 6 Months ( 180 Days ), Equipment by Equipment by CCTV Supplier | O35: =VLOOKUP($B35,BOM!$A$2:$K$94,10,0) -> 0 | P35: =O35*E35 -> 0
C36: UPS 10KVA - backup 15 min | D36: set | E36: 1 | O36: =VLOOKUP($B36,BOM!$A$2:$K$94,10,0) -> 0 | P36: =O36*E36 -> 0
B37: SRT10KRMXLI | C37: APC Smart UPS SRT10KRMXLIT-IEC UPS Battery Set (Replacement) | D37: set | E37: 0 | J37: 4 | L37: 8 tuần | M37: Vietrack | N37: Cái | O37: =VLOOKUP($B37,BOM!$A$2:$K$94,10,0) -> 0 | P37: =O37*E37 -> 0
B38: SRT192RMBP2 | C38: External battery lưu điện 15 phút 8kw | D38: set | E38: 0 | J38: 4 | L38: 8 tuần | M38: Vietrack | N38: Cái | O38: =VLOOKUP($B38,BOM!$A$2:$K$94,10,0) -> 0 | P38: =O38*E38 -> 0
C39: Accessory: Fan, socket outlet; Patch cord, Pigtail…. | D39: set | E39: 1 | O39: =VLOOKUP($B39,BOM!$A$2:$K$94,10,0) -> 0 | P39: =O39*E39 -> 0
C40: Oulet | O40: =VLOOKUP($B40,BOM!$A$2:$K$94,10,0) -> 0 | P40: =O40*E40 -> 0
...

Sheet data-tel 
B1: SUNTORY PEPSI LONG AN PROJECT - ME WORKS | G1: core SM | H1: core MM | J1: Rack Unit
B2: STT | C2: ITEMS | D2: UNIT | E2: Qty | F2: Used for | G2: Power Consumption | H2: REMARK
A3: 0 | C3: IDF SECURITY ROOM | D3: set | E3: 1 | K3: COO | L3: Delivery time | M3: Brand Name | N3: UOM | O3: Price | P3: sum
C4: CABINET | D4: set | E4: 1
O5: =VLOOKUP($B5,BOM!$A$2:$K$94,10,0) -> 0 | Q5: =VLOOKUP($B5,BOM!$A$2:$K$94,9,0) -> 0
O6: =VLOOKUP($B6,BOM!$A$2:$K$94,10,0) -> 0 | Q6: =VLOOKUP($B6,BOM!$A$2:$K$94,9,0) -> 0
O7: =VLOOKUP($B7,BOM!$A$2:$K$94,10,0) -> 0 | Q7: =VLOOKUP($B7,BOM!$A$2:$K$94,9,0) -> 0
C8: ODF | D8: set | E8: 1 | G8: =ROUNDUP(G3/24,0) -> 0 | H8: =ROUNDUP(H3/24,0) -> 0 | O8: =VLOOKUP($B8,BOM!$A$2:$K$94,10,0) -> 0 | P8: =O8*E8 -> 0 | Q8: =VLOOKUP($B8,BOM!$A$2:$K$94,9,0) -> 0
B9: 760249997 | C9: EPX-1U-PNL-ENC | D9: Cái | E9: =ROUNDUP(E11/3,0) -> 0 | K9: CN | L9: 8 tuần | M9: Commscope | N9: Cái | O9: =VLOOKUP($B9,BOM!$A$2:$K$94,10,0) -> 0 | P9: =O9*E9 -> 0 | Q9: =VLOOKUP($B9,BOM!$A$2:$K$94,9,0) -> Cái
B10: 760241378 | C10: CommScope® 48 Fibers Slicing Tray Kit | D10: Cái | E10: 0 | K10: CN | L10: 8 tuần | M10: Commscope | N10: Cái | O10: =VLOOKUP($B10,BOM!$A$2:$K$94,10,0) -> 0 | P10: =O10*E10 -> 0 | Q10: =VLOOKUP($B10,BOM!$A$2:$K$94,9,0) -> Cái
B11: EK5809-001 | C11: CommScope® 1000-type Adapter Plate 12 LC/UPC Duplex SM, Blue | D11: Cái | E11: =SUM(G8:I8) -> 0 | K11: CN | L11: 8 tuần | M11: Commscope | N11: Cái | O11: =VLOOKUP($B11,BOM!$A$2:$K$94,10,0) -> 0 | P11: =O11*E11 -> 0 | Q11: =VLOOKUP($B11,BOM!$A$2:$K$94,9,0) -> Cái
B12: EM2454-001 | C12: ADAPTER PLATE BLANK ASSY | D12: Cái | E12: =E9*3-E11 -> 0 | K12: CN | L12: 8 tuần | M12: Commscope | N12: Cái | O12: =VLOOKUP($B12,BOM!$A$2:$K$94,10,0) -> 0 | P12: =O12*E12 -> 0 | Q12: =VLOOKUP($B12,BOM!$A$2:$K$94,9,0) -> Cái
B13: 2105081-2 | C13: LC TO LC 0.9mm SM LSZH 2M | D13: sợi | E13: {=SUM(G3:I3/2)} -> 0 | K13: CN | L13: 8 tuần | M13: Commscope | N13: Sợi | O13: =VLOOKUP($B13,BOM!$A$2:$K$94,10,0) -> 0 | P13: =O13*E13 -> 0 | Q13: =VLOOKUP($B13,BOM!$A$2:$K$94,9,0) -> Sợi
B14: 2105028-3 | C14: COMMSCOPE/ AMP Fiber Optic Cable Assembly, Duplex LC, OS2, 3m | D14: sợi | E14: 0 | K14: CN | L14: 8 tuần | M14: Commscope | N14: Sợi | O14: =VLOOKUP($B14,BOM!$A$2:$K$94,10,0) -> 0 | P14: =O14*E14 -> 0 | Q14: =VLOOKUP($B14,BOM!$A$2:$K$94,9,0) -> Sợi
B15: EK5808-001 | C15: ADAPTER PLATE ASSY 12 LC DUP AQUA | D15: Cái | E15: =SUM(G12:I12) -> 0 | K15: CN | L15: 8 tuần | M15: Commscope | N15: Sợi | O15: =VLOOKUP($B15,BOM!$A$2:$K$94,10,0) -> 0 | P15: =O15*E15 -> 0 | Q15: =VLOOKUP($B15,BOM!$A$2:$K$94,9,0) -> Cái
B16: 2105061-3 | C16: LC TO LC 1.8mm OM4 DPX LSZH AND OFNR 3M | D16: sợi | E16: {=SUM(G5:I5/2)} -> 0 | K16: CN | L16: 8 tuần | M16: Commscope | N16: Sợi | O16: =VLOOKUP($B16,BOM!$A$2:$K$94,10,0) -> 0 | P16: =O16*E16 -> 0 | Q16: =VLOOKUP($B16,BOM!$A$2:$K$94,9,0) -> Cái
B17: 2105084-2 | C17: LC TO LC 0.9mm OM4 LSZH 2M | D17: sợi | E17: 0 | K17: CN | L17: 8 tuần | M17: Commscope | N17: Sợi | O17: =VLOOKUP($B17,BOM!$A$2:$K$94,10,0) -> 0 | P17: =O17*E17 -> 0 | Q17: =VLOOKUP($B17,BOM!$A$2:$K$94,9,0) -> Cái
C18: Patch panel | D18: set | O18: =VLOOKUP($B18,BOM!$A$2:$K$94,10,0) -> 0 | P18: =O18*E18 -> 0 | Q18: =VLOOKUP($B18,BOM!$A$2:$K$94,9,0) -> 0
B19: 760237046 | C19: CPP-SDDM-SL-1U-24: CommScope® SL DDM Patch Panel, STP, 1U, 24 port, Straight, Unload | D19: Cái | E19: =E23+E28 -> 0 | K19: CN | L19: 8 tuần | M19: Commscope | N19: Cái | O19: =VLOOKUP($B19,BOM!$A$2:$K$94,10,0) -> 0 | P19: =O19*E19 -> 0 | Q19: =VLOOKUP($B19,BOM!$A$2:$K$94,9,0) -> Cái
B20: VRMH01-1F | C20: Horizontal Cable Management 1U, Finger Duct, Black | D20: Cái | E20: =E19 -> 0 | K20: CN | L20: 8 tuần | M20: Vietrack | N20: Cái | O20: =VLOOKUP($B20,BOM!$A$2:$K$94,10,0) -> 0 | P20: =O20*E20 -> 0 | Q20: =VLOOKUP($B20,BOM!$A$2:$K$94,9,0) -> Cái
B21: 2153449-2 | C21: NetConnect® SLX Jack, Category 6A, S/FTP, without Dust Cover, Black | D21: Cái | E21: =E19*24 -> 0 | K21: MX | L21: 8 tuần | M21: Commscope | N21: Cái | O21: =VLOOKUP($B21,BOM!$A$2:$K$94,10,0) -> 0 | P21: =O21*E21 -> 0 | Q21: =VLOOKUP($B21,BOM!$A$2:$K$94,9,0) -> Cái
O22: =VLOOKUP($B22,BOM!$A$2:$K$94,10,0) -> 0 | P22: =O22*E22 -> 0 | Q22: =VLOOKUP($B22,BOM!$A$2:$K$94,9,0) -> 0
O23: =VLOOKUP($B23,BOM!$A$2:$K$94,10,0) -> 0 | P23: =O23*E23 -> 0 | Q23: =VLOOKUP($B23,BOM!$A$2:$K$94,9,0) -> 0
O24: =VLOOKUP($B24,BOM!$A$2:$K$94,10,0) -> 0 | P24: =O24*E24 -> 0 | Q24: =VLOOKUP($B24,BOM!$A$2:$K$94,9,0) -> 0
O25: =VLOOKUP($B25,BOM!$A$2:$K$94,10,0) -> 0 | P25: =O25*E25 -> 0 | Q25: =VLOOKUP($B25,BOM!$A$2:$K$94,9,0) -> 0
O26: =VLOOKUP($B26,BOM!$A$2:$K$94,10,0) -> 0 | P26: =O26*E26 -> 0 | Q26: =VLOOKUP($B26,BOM!$A$2:$K$94,9,0) -> 0
C27: Switch POE 24 Ports for CCTV | D27: set | E27: 3 | O27: =VLOOKUP($B27,BOM!$A$2:$K$94,10,0) -> 0 | P27: =O27*E27 -> 0 | Q27: =VLOOKUP($B27,BOM!$A$2:$K$94,9,0) -> 0
O28: =VLOOKUP($B28,BOM!$A$2:$K$94,10,0) -> 0 | P28: =O28*E28 -> 0 | Q28: =VLOOKUP($B28,BOM!$A$2:$K$94,9,0) -> 0
O29: =VLOOKUP($B29,BOM!$A$2:$K$94,10,0) -> 0 | P29: =O29*E29 -> 0 | Q29: =VLOOKUP($B29,BOM!$A$2:$K$94,9,0) -> 0
C30: IP AMPLIFIER (240W) | D30: set | E30: 1 | H30: Equipment by PA Supplier | O30: =VLOOKUP($B30,BOM!$A$2:$K$94,10,0) -> 0 | P30: =O30*E30 -> 0 | Q30: =VLOOKUP($B30,BOM!$A$2:$K$94,9,0) -> 0
C31: Network Module | D31: set | E31: 1 | G31: Pulic Address | H31: Equipment by PA Supplier | O31: =VLOOKUP($B31,BOM!$A$2:$K$94,10,0) -> 0 | P31: =O31*E31 -> 0 | Q31: =VLOOKUP($B31,BOM!$A$2:$K$94,9,0) -> 0
C32: Network Audio Interface Unit | D32: set | E32: 1 | G32: Pulic Address | H32: Equipment by PA Supplier | O32: =VLOOKUP($B32,BOM!$A$2:$K$94,10,0) -> 0 | P32: =O32*E32 -> 0 | Q32: =VLOOKUP($B32,BOM!$A$2:$K$94,9,0) -> 0
C33: IP-1000CI TOA (32 ports) | D33: set | E33: 1 | H33: Equipment by PA Supplier | O33: =VLOOKUP($B33,BOM!$A$2:$K$94,10,0) -> 0 | P33: =O33*E33 -> 0 | Q33: =VLOOKUP($B33,BOM!$A$2:$K$94,9,0) -> 0
C34: IP -GATEWAY | D34: set | E34: 1 | H34: Equipment by PA Supplier | O34: =VLOOKUP($B34,BOM!$A$2:$K$94,10,0) -> 0 | P34: =O34*E34 -> 0 | Q34: =VLOOKUP($B34,BOM!$A$2:$K$94,9,0) -> 0
C35: Storage sever 1~6 | D35: set | E35: 1 | H35: 6 Months ( 180 Days ), Equipment by Equipment by CCTV Supplier | O35: =VLOOKUP($B35,BOM!$A$2:$K$94,10,0) -> 0 | P35: =O35*E35 -> 0 | Q35: =VLOOKUP($B35,BOM!$A$2:$K$94,9,0) -> 0
C36: UPS 10KVA - backup 15 min | D36: set | E36: 1 | O36: =VLOOKUP($B36,BOM!$A$2:$K$94,10,0) -> 0 | P36: =O36*E36 -> 0 | Q36: =VLOOKUP($B36,BOM!$A$2:$K$94,9,0) -> 0
O37: =VLOOKUP($B37,BOM!$A$2:$K$94,10,0) -> 0 | P37: =O37*E37 -> 0 | Q37: =VLOOKUP($B37,BOM!$A$2:$K$94,9,0) -> 0
O38: =VLOOKUP($B38,BOM!$A$2:$K$94,10,0) -> 0 | P38: =O38*E38 -> 0 | Q38: =VLOOKUP($B38,BOM!$A$2:$K$94,9,0) -> 0
C39: Accessory: Fan, socket outlet; Patch cord, Pigtail…. | D39: set | E39: 1 | O39: =VLOOKUP($B39,BOM!$A$2:$K$94,10,0) -> 0 | P39: =O39*E39 -> 0 | Q39: =VLOOKUP($B39,BOM!$A$2:$K$94,9,0) -> 0
C40: Oulet | O40: =VLOOKUP($B40,BOM!$A$2:$K$94,10,0) -> 0 | P40: =O40*E40 -> 0 | Q40: =VLOOKUP($B40,BOM!$A$2:$K$94,9,0) -> 0
...

Sheet BOM
A1: PN | B1: MÔ TẢ | D1: Xuất xứ | E1: đặt hàng | F1: NHÀ SX | H1: SL Mới | I1: ĐVT | M1: CCTV | P1: Tel+data
B2: Oulet
A3: 272368-1 | B3: COMMSCOPE/ AMP US Style Low Profile Faceplate, 1-Port Shuttered, w/Label & Icon, Almond | C3: Outlet, can combie to socket | D3: Thái Lan | E3: 8 tuần | F3: Commscope | I3: Cái | M3: =SUMIF(CCTV!B:B,A3,CCTV!E:E) -> 0 | N3: =M3*J3 -> 0 | P3: =SUMIF('data-tel '!B:B,A3,'data-tel '!E:E) -> 153 | Q3: =P3*J3 -> 0 | R3: =J3*P3 -> 0
A4: NSP-USMB | B4: Đế sâu 60mm cho jack Cat6A FTP | C4: đế | D4: VN | E4: 8 tuần | F4: VN | I4: Cái | M4: =SUMIF(CCTV!B:B,A4,CCTV!E:E) -> 0 | N4: =M4*J4 -> 0 | P4: =SUMIF('data-tel '!B:B,A4,'data-tel '!E:E) -> 153 | Q4: =P4*J4 -> 0 | R4: =J4*P4 -> 0
A5: 2153449-1 | B5: NetConnect® SLX Jack, Category 6A, S/FTP, without Dust Cover, Almond | C5: Modular Jack, RJ45, Cat6A Shielded | D5: MX | E5: 8 tuần | F5: Commscope | I5: Cái | M5: =SUMIF(CCTV!B:B,A5,CCTV!E:E) -> 0 | N5: =M5*J5 -> 0 | P5: =SUMIF('data-tel '!B:B,A5,'data-tel '!E:E) -> 153 | Q5: =P5*J5 -> 0 | R5: =J5*P5 -> 0
B6: Đấu nối cho Camera-wifi-và các thiết bị gắn trần | H6: =M6+P6 -> 0 | M6: =SUMIF(CCTV!B:B,A6,CCTV!E:E) -> 0 | N6: =M6*J6 -> 0 | P6: =SUMIF('data-tel '!B:B,A6,'data-tel '!E:E) -> 0 | Q6: =P6*J6 -> 0 | R6: =J6*P6 -> 0
A7: NPC6ASZDB-WT002M | B7: NetConnect® Patch cord, Category 6A, 4pair, Stranded S/FTP, LSZH, White, 2 m | C7: Patch cord | D7: CN | E7: 8 tuần | F7: Commscope | G7: 910 | H7: =M7+P7+25 -> 910 | I7: Sợi | M7: =SUMIF(CCTV!B:B,A7,CCTV!E:E) -> 545 | N7: =M7*J7 -> 0 | P7: =SUMIF('data-tel '!B:B,A7,'data-tel '!E:E) -> 340 | Q7: =P7*J7 -> 0 | R7: =J7*P7 -> 0
A8: 5-1933433-3 | B8: KIT,8P,MP,.310 ,CAT6/6A,SHIELDED, 100PC | C8: Cos mạng | D8: CN | E8: 8 tuần | F8: Commscope | G8: 609 | H8: =M8+P8 -> 609 | I8: Cái | M8: =SUMIF(CCTV!B:B,A8,CCTV!E:E) -> 488 | N8: =M8*J8 -> 0 | P8: =SUMIF('data-tel '!B:B,A8,'data-tel '!E:E) -> 121 | Q8: =P8*J8 -> 0 | R8: =J8*P8 -> 0
A9: 1933943-2 | B9: BOOT, HOODED, 0.310 GRAY | C9: Miếng nhưa cover cos mạng | D9: Cái | E9: CN | F9: 8 tuần | G9: 609 | H9: =M9+P9 -> 609 | I9: Cái | M9: =SUMIF(CCTV!B:B,A9,CCTV!E:E) -> 488 | N9: =M9*J9 -> 0 | P9: =SUMIF('data-tel '!B:B,A9,'data-tel '!E:E) -> 121 | Q9: =P9*J9 -> 0 | R9: =J9*P9 -> 0
A10: 760249003 | B10: Crimp Tool 8P, Sentinel 900020 | C10: Kiềm Bấm | E10: 8 tuần | F10: Commscope | G10: 1 | H10: =M10+P10 -> 1 | I10: Cái | M10: =SUMIF(CCTV!B:B,A10,CCTV!E:E) -> 0 | N10: =M10*J10 -> 0 | P10: =SUMIF('data-tel '!B:B,A10,'data-tel '!E:E) -> 1 | Q10: =P10*J10 -> 0 | R10: =J10*P10 -> 0
B11: dây nhảy | H11: =M11+P11 -> 0 | M11: =SUMIF(CCTV!B:B,A11,CCTV!E:E) -> 0 | N11: =M11*J11 -> 0 | P11: =SUMIF('data-tel '!B:B,A11,'data-tel '!E:E) -> 0 | Q11: =P11*J11 -> 0 | R11: =J11*P11 -> 0
A12: NPC6ASZDB-WT003M | B12: NetConnect® Patch cord, Category 6A, 4pair, Stranded S/FTP, LSZH, White, 3 m | C12: Patch cord | E12: 8 tuần | F12: Commscope | G12: 300 | H12: =M12+P12+31 -> 300 | I12: Sợi | M12: =SUMIF(CCTV!B:B,A12,CCTV!E:E) -> 167 | N12: =M12*J12 -> 0 | P12: =SUMIF('data-tel '!B:B,A12,'data-tel '!E:E) -> 102 | Q12: =P12*J12 -> 0 | R12: =J12*P12 -> 0
B13: ODF | H13: =M13+P13 -> 0 | M13: =SUMIF(CCTV!B:B,A13,CCTV!E:E) -> 0 | N13: =M13*J13 -> 0 | P13: =SUMIF('data-tel '!B:B,A13,'data-tel '!E:E) -> 0 | Q13: =P13*J13 -> 0 | R13: =J13*P13 -> 0
A14: 760249997 | B14: EPX-1U-PNL-ENC | C14: ODF | D14: CN | E14: 8 tuần | F14: Commscope | G14: 57 | H14: =M14+P14 -> 57 | I14: Cái | M14: =SUMIF(CCTV!B:B,A14,CCTV!E:E) -> 29 | N14: =M14*J14 -> 0 | P14: =SUMIF('data-tel '!B:B,A14,'data-tel '!E:E) -> 28 | Q14: =P14*J14 -> 0 | R14: =J14*P14 -> 0
A15: 760241378 | B15: CommScope® 48 Fibers Slicing Tray Kit | C15: Fiber Optic Splice Tray Kit | D15: CN | E15: 8 tuần | F15: Commscope | G15: 63 | H15: =M15+P15 -> 63 | I15: Cái | M15: =SUMIF(CCTV!B:B,A15,CCTV!E:E) -> 31 | N15: =M15*J15 -> 0 | P15: =SUMIF('data-tel '!B:B,A15,'data-tel '!E:E) -> 32 | Q15: =P15*J15 -> 0 | R15: =J15*P15 -> 0
A16: EK5809-001 | B16: CommScope® 1000-type Adapter Plate 12 LC/UPC Duplex SM, Blue | C16: 1000-Type Adapter Pack with 12 LC duplex SM adapters | D16: CN | E16: 8 tuần | F16: Commscope | G16: 57 | H16: =M16+P16 -> 57 | I16: Cái | M16: =SUMIF(CCTV!B:B,A16,CCTV!E:E) -> 35 | N16: =M16*J16 -> 0 | P16: =SUMIF('data-tel '!B:B,A16,'data-tel '!E:E) -> 22 | Q16: =P16*J16 -> 0 | R16: =J16*P16 -> 0
A17: EK5808-001 | B17: ADAPTER PLATE ASSY 12 LC DUP AQUA | C17: ??? | D17: CN | E17: 8 tuần | F17: Commscope | G17: 23 | H17: =M17+P17 -> 23 | I17: Cái | M17: =SUMIF(CCTV!B:B,A17,CCTV!E:E) -> 0 | N17: =M17*J17 -> 0 | P17: =SUMIF('data-tel '!B:B,A17,'data-tel '!E:E) -> 23 | Q17: =P17*J17 -> 0 | R17: =J17*P17 -> 0
A18: EM2454-001 | B18: ADAPTER PLATE BLANK ASSY | C18: blank, black | D18: CN | E18: 8 tuần | F18: Commscope | G18: 91 | H18: =M18+P18 -> 91 | I18: Cái | M18: =SUMIF(CCTV!B:B,A18,CCTV!E:E) -> 52 | N18: =M18*J18 -> 0 | P18: =SUMIF('data-tel '!B:B,A18,'data-tel '!E:E) -> 39 | Q18: =P18*J18 -> 0 | R18: =J18*P18 -> 0
A19: 2105061-3 | B19: LC TO LC 1.8mm OM4 DPX LSZH AND OFNR 3M | C19: Fiber Patch cord | D19: CN | E19: 8 tuần | F19: Commscope | G19: 124 | H19: =M19+P19 -> 124 | I19: Cái | M19: =SUMIF(CCTV!B:B,A19,CCTV!E:E) -> 0 | N19: =M19*J19 -> 0 | P19: =SUMIF('data-tel '!B:B,A19,'data-tel '!E:E) -> 124 | Q19: =P19*J19 -> 0 | R19: =J19*P19 -> 0
A20: 2105084-2 | B20: LC TO LC 0.9mm OM4 LSZH 2M | C20: Fiber Patch cord | D20: CN | E20: 8 tuần | F20: Commscope | G20: 192 | H20: =M20+P20 -> 192 | I20: Cái | M20: =SUMIF(CCTV!B:B,A20,CCTV!E:E) -> 0 | N20: =M20*J20 -> 0 | P20: =SUMIF('data-tel '!B:B,A20,'data-tel '!E:E) -> 192 | Q20: =P20*J20 -> 0 | R20: =J20*P20 -> 0
A21: 2105081-2 | B21: LC TO LC 0.9mm SM LSZH 2M | C21: Fiber Patch cord | D21: CN | E21: 8 tuần | F21: Commscope | G21: 462 | H21: =M21+P21 -> 462 | I21: Sợi | M21: =SUMIF(CCTV!B:B,A21,CCTV!E:E) -> 212 | N21: =M21*J21 -> 0 | P21: =SUMIF('data-tel '!B:B,A21,'data-tel '!E:E) -> 250 | Q21: =P21*J21 -> 0 | R21: =J21*P21 -> 0
A22: 2105028-3 | B22: COMMSCOPE/ AMP Fiber Optic Cable Assembly, Duplex LC, OS2, 3m | C22: Fiber Patch cord | D22: CN | E22: 8 tuần | F22: Commscope | G22: 225 | H22: =M22+P22 -> 225 | I22: Sợi | M22: =SUMIF(CCTV!B:B,A22,CCTV!E:E) -> 119 | N22: =M22*J22 -> 0 | P22: =SUMIF('data-tel '!B:B,A22,'data-tel '!E:E) -> 106 | Q22: =P22*J22 -> 0 | R22: =J22*P22 -> 0
B23: Patch panel | H23: =M23+P23 -> 0 | M23: =SUMIF(CCTV!B:B,A23,CCTV!E:E) -> 0 | N23: =M23*J23 -> 0 | P23: =SUMIF('data-tel '!B:B,A23,'data-tel '!E:E) -> 0 | Q23: =P23*J23 -> 0 | R23: =J23*P23 -> 0
A24: 760237046 | B24: CPP-SDDM-SL-1U-24: CommScope® SL DDM Patch Panel, STP, 1U, 24 port, Straight, Unload | C24: Patch Panel | D24: CN | E24: 8 tuần | F24: Commscope | G24: 66 | H24: =M24+P24 -> 66 | I24: Cái | M24: =SUMIF(CCTV!B:B,A24,CCTV!E:E) -> 39 | N24: =M24*J24 -> 0 | P24: =SUMIF('data-tel '!B:B,A24,'data-tel '!E:E) -> 27 | Q24: =P24*J24 -> 0 | R24: =J24*P24 -> 0
A25: 2153449-2 | B25: NetConnect® SLX Jack, Category 6A, S/FTP, without Dust Cover, Black | C25: Cos mạng | D25: MX | E25: 8 tuần | F25: Commscope | G25: 1584 | H25: =M25+P25 -> 1584 | I25: Cái | M25: =SUMIF(CCTV!B:B,A25,CCTV!E:E) -> 936 | N25: =M25*J25 -> 0 | P25: =SUMIF('data-tel '!B:B,A25,'data-tel '!E:E) -> 648 | Q25: =P25*J25 -> 0 | R25: =J25*P25 -> 0
A26: VRMH01-1F | B26: Horizontal Cable Management 1U, Finger Duct, Black | C26: thanh ngang | D26: CN | E26: 8 tuần | F26: Vietrack | G26: 66 | H26: =M26+P26 -> 66 | I26: Cái | M26: =SUMIF(CCTV!B:B,A26,CCTV!E:E) -> 39 | N26: =M26*J26 -> 0 | P26: =SUMIF('data-tel '!B:B,A26,'data-tel '!E:E) -> 27 | Q26: =P26*J26 -> 0 | R26: =J26*P26 -> 0
B27: UPS | H27: =M27+P27 -> 0 | M27: =SUMIF(CCTV!B:B,A27,CCTV!E:E) -> 0 | N27: =M27*J27 -> 0 | P27: =SUMIF('data-tel '!B:B,A27,'data-tel '!E:E) -> 0 | Q27: =P27*J27 -> 0 | R27: =J27*P27 -> 0
A28: SRV1KIL-E | B28: SRV1KIL-E - APC Easy UPS On-Line, 1000VA/800W, Tower | C28: UPS Tower | D28: CN | E28: 12-14 tuần | F28: schneider APC | I28: Cái | M28: =SUMIF(CCTV!B:B,A28,CCTV!E:E) -> 15 | N28: =M28*J28 -> 0 | P28: =SUMIF('data-tel '!B:B,A28,'data-tel '!E:E) -> 0 | Q28: =P28*J28 -> 0 | R28: =J28*P28 -> 0
A29: SRV2KIL-E | B29: SRV2KIL-E - APC Easy UPS On-Line, 2000VA/1600W, Tower | C29: UPS Tower | D29: CN | E29: 12-14 tuần | F29: schneider APC | I29: Cái | M29: =SUMIF(CCTV!B:B,A29,CCTV!E:E) -> 3 | N29: =M29*J29 -> 0 | P29: =SUMIF('data-tel '!B:B,A29,'data-tel '!E:E) -> 17 | Q29: =P29*J29 -> 0 | R29: =J29*P29 -> 0
A30: SRV3KIL-E | B30: SRV6KIL - APC Easy UPS On-Line, 6kVA/6kW, Tower, 230V | C30: UPS Tower | D30: CN | E30: 12-14 tuần | F30: schneider APC | I30: Cái | M30: =SUMIF(CCTV!B:B,A30,CCTV!E:E) -> 1 | N30: =M30*J30 -> 0 | P30: =SUMIF('data-tel '!B:B,A30,'data-tel '!E:E) -> 2 | Q30: =P30*J30 -> 0 | R30: =J30*P30 -> 0
A31: SRT5KRMXLI | B31: APC Smart-UPS On-Line, 5kVA, Rackmount 2U, 230V, 8x C13+2x C19 IEC outlets, SmartSlot, Extended runtime, W/ rail kit | C31: UPS IDF 1.3 | D31: CN | E31: 12-14 tuần | F31: schneider APC | I31: Cái | M31: =SUMIF(CCTV!B:B,A31,CCTV!E:E) -> 1 | N31: =M31*J31 -> 0 | P31: =SUMIF('data-tel '!B:B,A31,'data-tel '!E:E) -> 0 | Q31: =P31*J31 -> 0 | R31: =J31*P31 -> 0
A32: SURT1000RMXLI | B32: APC Smart-UPS RT 1000VA, 230V, rackmount, 2U, 6x IEC 60320 & 2x IEC Jumpers outlets | C32: rackmount | D32: CN | E32: 12-14 tuần | F32: schneider APC | I32: Cái | M32: =SUMIF(CCTV!B:B,A32,CCTV!E:E) -> 2 | N32: =M32*J32 -> 0 | P32: =SUMIF('data-tel '!B:B,A32,'data-tel '!E:E) -> 0 | Q32: =P32*J32 -> 0 | R32: =J32*P32 -> 0
A33: SRT2200RMXLI | B33: APC Smart-UPS On-Line, 2200VA, Rackmount 2U, 230V, 8x C13+2x C19 IEC outlets, SmartSlot, Extended runtime, W/ rail kit | C33: rackmount | D33: CN | E33: 12-14 tuần | F33: schneider APC | I33: Cái | M33: =SUMIF(CCTV!B:B,A33,CCTV!E:E) -> 1 | N33: =M33*J33 -> 0 | P33: =SUMIF('data-tel '!B:B,A33,'data-tel '!E:E) -> 1 | Q33: =P33*J33 -> 0 | R33: =J33*P33 -> 0
A34: SRT3000RMXLI | B34: APC Smart-UPS On-Line, 3kVA, Rackmount 2U, 230V, 8x C13+2x C19 IEC outlets, SmartSlot, Extended runtime, W/ rail kit | C34: rackmount | D34: CN | E34: 12-14 tuần | F34: schneider APC | I34: Cái | M34: =SUMIF(CCTV!B:B,A34,CCTV!E:E) -> 2 | N34: =M34*J34 -> 0 | P34: =SUMIF('data-tel '!B:B,A34,'data-tel '!E:E) -> 0 | Q34: =P34*J34 -> 0 | R34: =J34*P34 -> 0
A35: SRT96RMBP | B35: External battery lưu điện 20 phút 2700w | D35: CN | E35: 12-14 tuần | F35: schneider APC | I35: Cái | M35: =SUMIF(CCTV!B:B,A35,CCTV!E:E) -> 0 | N35: =M35*J35 -> 0 | P35: =SUMIF('data-tel '!B:B,A35,'data-tel '!E:E) -> 0 | Q35: =P35*J35 -> 0 | R35: =J35*P35 -> 0
A36: AP9544 | B36: Card SNMP cho ups 3kva | D36: CN | E36: 12-14 tuần | F36: schneider APC | I36: Cái | M36: =SUMIF(CCTV!B:B,A36,CCTV!E:E) -> 0 | N36: =M36*J36 -> 0 | P36: =SUMIF('data-tel '!B:B,A36,'data-tel '!E:E) -> 0 | Q36: =P36*J36 -> 0 | R36: =J36*P36 -> 0
A37: SRT10KRMXLI | B37: APC Smart UPS SRT10KRMXLIT-IEC UPS Battery Set (Replacement) | C37: Đã bao gồm card modbus chưa: đã bao gồm tích hợp sẳn | D37: CN | E37: 12-14 tuần | F37: schneider APC | I37: Cái | M37: =SUMIF(CCTV!B:B,A37,CCTV!E:E) -> 0 | N37: =M37*J37 -> 0 | P37: =SUMIF('data-tel '!B:B,A37,'data-tel '!E:E) -> 2 | Q37: =P37*J37 -> 0 | R37: =J37*P37 -> 0
A38: SRT192RMBP2 | B38: External battery lưu điện 15 phút 8kw | D38: CN | E38: 12-14 tuần | F38: schneider APC | I38: Cái | M38: =SUMIF(CCTV!B:B,A38,CCTV!E:E) -> 0 | N38: =M38*J38 -> 0 | P38: =SUMIF('data-tel '!B:B,A38,'data-tel '!E:E) -> 2 | Q38: =P38*J38 -> 0 | R38: =J38*P38 -> 0
A39: SRV-UPSINST | B39: Phí Lắp đặt UPS | G39: 47 | H39: =M39+P39 -> 47 | I39: bộ | M39: =SUMIF(CCTV!B:B,A39,CCTV!E:E) -> 25 | N39: =M39*J39 -> 0 | P39: =SUMIF('data-tel '!B:B,A39,'data-tel '!E:E) -> 22 | Q39: =P39*J39 -> 0 | R39: =J39*P39 -> 0
B40: tủ Rack | H40: =M40+P40 -> 0 | M40: =SUMIF(CCTV!B:B,A40,CCTV!E:E) -> 0 | N40: =M40*J40 -> 0 | P40: =SUMIF('data-tel '!B:B,A40,'data-tel '!E:E) -> 0 | Q40: =P40*J40 -> 0 | R40: =J40*P40 -> 0
...
